Workbook

Sheet PERTANYAAN
A1: FORM PENILAIAN PEGAWAI & CALON PEGAWAI
A2: DANISWARA GROUP
A5: NAMA | B5: :
A6: POSISI PELAMAR | B6: : | C6: STAFF OPERASI
A7: PENEMPATAN | B7: : | C7: IKN - KALIMANTAN TIMUR
A8: DIVISI | B8: : | C8: OPERASI
A9: BUDGET SALARY | B9: : | C9: RANGE 4 JT - 4,8 JT (ALL IN - IKN)
A10: HR | B10: : | C10: ANGGY PERMANA PUTRA
A11: HASIL PENILAIAN | B11: : | C11: =N16 -> 86.7
A13: KODE ACC | B13: NO. | C13: KATEGORI | D13: PERTANYAAN | E13: BOBOT | G13: CHECK | I13: PENILAIAN | N13: HASIL | O13: KETERANGAN
G14: ADA | H14: TIDAK | I14: SK | J14: K | K14: R | L14: B | M14: SB
A15: 1 | B15: =A15+1 -> 2 | C15: =B15+1 -> 3 | D15: =C15+1 -> 4 | E15: =D15+1 -> 5 | I15: 0.2 | J15: 0.4 | K15: 0.6 | L15: 0.8 | M15: 1
C16: GRAND TOTAL PENILAIAN | E16: =E17+E21+E27+E43+E60+E65+E69 -> 1 | N16: =N17+N21+N27+N43+N60+N65+N69 -> 86.7
B17: A | C17: PENGALAMAN | E17: =SUM(E18:E19) -> 0.1 | N17: =SUM(N18:N20) -> 10
A18: A100 | B18: 1 | C18: Pengalaman di dalam Daniswara Group | D18: Apakah ada Pengalaman di Daniswara Group? Bagaimana pandangan anda terkait Daniswara Group? | E18: 0.06 | G18: V | N18: =IF(G18="V",E18*100,0) -> 6
A19: A200 | B19: =B18+1 -> 2 | C19: Pengalaman di luar Daniswara Group | D19: Jika tidak, apakah sudah ada pengalaman sejenis di luar Daniswara? | E19: 0.04 | G19: V | N19: =IF(G19="V",E19*100,0) -> 4
B21: B | C21: ADMINISTRASI | E21: =SUM(E22:E25) -> 0.05 | N21: =SUM(N22:N25) -> 5
A22: B100 | B22: 1 | C22: Identitas (KTP & KK) | D22: Apakah ada Identitas Diri KTP & KK? | E22: 0.01 | G22: V | N22: =IF(G22="V",E22*100,0) -> 1
A23: B200 | B23: =B22+1 -> 2 | C23: SIM A (utk jabatan di Divisi Operasi) | D23: Apakah sudah memiliki SIM A? | E23: 0.02 | G23: V | N23: =IF(G23="V",E23*100,0) -> 2
A24: B300 | B24: =B23+1 -> 3 | C24: SIM C | D24: Apakah sudah memiliki SIM C? | E24: 0.01 | G24: V | N24: =IF(G24="V",E24*100,0) -> 1
A25: B400 | B25: =B24+1 -> 4 | C25: NPWP | D25: Apakah sudah Memiliki NPWP? | E25: 0.01 | G25: V | N25: =IF(G25="V",E25*100,0) -> 1
B27: C | C27: HARD SKILL | E27: =E28 -> 0.35 | N27: =N28 -> 28.5
A28: C100 | B28: 1 | C28: Operasi / Logistik | E28: =SUM(E29:E32) -> 0.35 | N28: =SUM(N29:N33) -> 28.5
A29: C110 | B29: - | C29: Skill Mengemudi | D29: Coba ceritakan pengalaman / keahlian dalam mengemudi mobil angkut/logistik? | E29: 0.15 | L29: V | N29: =IF(I29="V",$E29*I$15,IF(J29="V",$E29*J$15,IF(K29="V",$E29*K$15,IF(L29="V",$E29*L$15,IF(M29="V",$E29*M$15,0)))))*100 -> 12
A30: C120 | B30: - | C30: Flow Administrasi Logistik | D30: Coba ceritakan yang anda ketahui tentang alur administrasi logistik? Dan kaitannya dengan Ms. Office | E30: 0.1 | M30: V | N30: =IF(I30="V",$E30*I$15,IF(J30="V",$E30*J$15,IF(K30="V",$E30*K$15,IF(L30="V",$E30*L$15,IF(M30="V",$E30*M$15,0)))))*100 -> 10
A31: C130 | B31: - | C31: Pengetahuan terkait logistik | D31: Ceritakan yang anda ketahui terkait dengan logistik? | E31: 0.025 | L31: V | N31: =IF(I31="V",$E31*I$15,IF(J31="V",$E31*J$15,IF(K31="V",$E31*K$15,IF(L31="V",$E31*L$15,IF(M31="V",$E31*M$15,0)))))*100 -> 2
A32: C140 | B32: - | C32: Pengalaman di Bongkar Muat | D32: Apakah memiliki pengalaman terkait bongkar muat?sedalam apa? | E32: 0.075 | K32: V | N32: =IF(I32="V",$E32*I$15,IF(J32="V",$E32*J$15,IF(K32="V",$E32*K$15,IF(L32="V",$E32*L$15,IF(M32="V",$E32*M$15,0)))))*100 -> 4.5
B34: =B28+1 -> 2 | C34: Keuangan | E34: =SUM(E35:E37) -> 0.35
B35: - | C35: Skill Akuntansi & Input Data | E35: 0.15
B36: - | C36: Microsoft Office | E36: 0.2
B38: 3 | C38: Busdev & HR
B39: - | C39: Pengalaman Kreatif
B40: - | C40: Organisasi Perusahaan & Lembaga
B41: -
B43: D | C43: SOFT SKILL | E43: =E44 -> 0.25 | N43: =N44 -> 22.5
A44: D100 | B44: 1 | C44: Staff | E44: =SUM(E45:E49) -> 0.25 | N44: =SUM(N45:N48) -> 22.5
A45: D110 | B45: - | C45: Kepemimpinan | D45: Jika terjadi suatu diskusi dalam group/kelompok yang belum menemukan titik temu, apa yang akan anda lakukan? | E45: 0.025 | L45: V | N45: =IF(I45="V",$E45*I$15,IF(J45="V",$E45*J$15,IF(K45="V",$E45*K$15,IF(L45="V",$E45*L$15,IF(M45="V",$E45*M$15,0)))))*100 -> 2
A46: D120 | B46: - | C46: Komunikasi | D46: Bagaimana hubungan kerjasama antar sesama pegawai / organisasi / kelompok?(jika memiliki pengalaman kerja) | E46: 0.1 | L46: V | N46: =IF(I46="V",$E46*I$15,IF(J46="V",$E46*J$15,IF(K46="V",$E46*K$15,IF(L46="V",$E46*L$15,IF(M46="V",$E46*M$15,0)))))*100 -> 8
A47: D130 | B47: - | C47: Patuh pada Peraturan / Commitment | D47: Bagaimana pandangan anda terkait perusahaan dan aturan yang dapat berubah ubah sesuai arah perusahaan? | E47: 0.05 | M47: V | N47: =IF(I47="V",$E47*I$15,IF(J47="V",$E47*J$15,IF(K47="V",$E47*K$15,IF(L47="V",$E47*L$15,IF(M47="V",$E47*M$15,0)))))*100 -> 5
A48: D140 | B48: - | C48: Determinasi thd tekanan | D48: Bagaimana pandangan anda jika anda dituntut pada pekerjaan diluar dari waktu normal dalam bekerja? | E48: 0.075 | M48: V | N48: =IF(I48="V",$E48*I$15,IF(J48="V",$E48*J$15,IF(K48="V",$E48*K$15,IF(L48="V",$E48*L$15,IF(M48="V",$E48*M$15,0)))))*100 -> 7.5
...

Sheet REKAP
A1: FORM PENILAIAN PEGAWAI & CALON PEGAWAI
A2: DANISWARA GROUP
B4: REKAP HASIL PENILAIAN PEGAWAI & CALON PEGAWAI
B6: NO. | C6: NAMA PERSONIL | D6: JABATAN / CALON POSISI | E6: PENILAIAN | I6: HASIL | J6: KETERANGAN | K6: CATATAN
E7: HR | F7: USER-1 | G7: USER-2 | H7: MANAGER
B9: 1 | C9: DENY FERDIANSYAH | D9: STAFF OPERASI - IKN | E9: =RESUME!G16 -> 70.8 | F9: =RESUME!H16 -> 66.2 | G9: =RESUME!I16 -> #REF! | H9: =RESUME!J16 -> #REF! | I9: =IFERROR(AVERAGE(E9:H9),0) -> 0 | J9: =IF(I9>=70,"LULUS",IF(I9>=60,"LULUS DENGAN CATATAN",IF(I9<60,"TIDAK LULUS",0))) -> TIDAK LULUS
B10: =B9+1 -> 2 | C10: DIAN | D10: STAFF OPERASI - DKI | I10: =IFERROR(AVERAGE(E10:H10),0) -> 0 | J10: =IF(I10>=70,"LULUS",IF(I10>=60,"LULUS DENGAN CATATAN",IF(I10<60,"TIDAK LULUS",0))) -> TIDAK LULUS
B11: =B10+1 -> 3 | C11: SADAM | D11: STAFF OPERASI - IKN | I11: =IFERROR(AVERAGE(E11:H11),0) -> 0 | J11: =IF(I11>=70,"LULUS",IF(I11>=60,"LULUS DENGAN CATATAN",IF(I11<60,"TIDAK LULUS",0))) -> TIDAK LULUS
B12: =B11+1 -> 4 | C12: IMAM | D12: STAFF OPERASI - IKN | I12: =IFERROR(AVERAGE(E12:H12),0) -> 0 | J12: =IF(I12>=70,"LULUS",IF(I12>=60,"LULUS DENGAN CATATAN",IF(I12<60,"TIDAK LULUS",0))) -> TIDAK LULUS
B13: =B12+1 -> 5 | C13: TAUFIK HIDAYATULLAH | D13: STAFF OPERASI - IKN | I13: =IFERROR(AVERAGE(E13:H13),0) -> 0 | J13: =IF(I13>=70,"LULUS",IF(I13>=60,"LULUS DENGAN CATATAN",IF(I13<60,"TIDAK LULUS",0))) -> TIDAK LULUS

Sheet RESUME
A1: FORM PENILAIAN PEGAWAI & CALON PEGAWAI
A2: DANISWARA GROUP
A5: NAMA | B5: : | C5: DENY
A6: POSISI PELAMAR | B6: : | C6: STAFF OPERASI
A7: PENEMPATAN | B7: : | C7: IKN - KALIMANTAN TIMUR
A8: DIVISI | B8: : | C8: OPERASI
A9: BUDGET SALARY | B9: : | C9: RANGE 4 JT - 4,8 JT (ALL IN - IKN)
A10: HR | B10: : | C10: ANGGY PERMANA PUTRA
A11: HASIL PENILAIAN | B11: : | C11: =K16 -> #REF!
A13: KODE ACC | B13: NO. | C13: KATEGORI | D13: PERTANYAAN | E13: BOBOT | G13: PENILAIAN | K13: HASIL | L13: KETERANGAN
G14: HR | H14: USER-1 | I14: USER-2 | J14: MANAGER
C16: GRAND TOTAL PENILAIAN | E16: =E17+E21+E27+E43+E60+E65+E69 -> 1 | G16: =G17+G21+G27+G43+G60+G65+G69 -> 70.8 | H16: =H17+H21+H27+H43+H60+H65+H69 -> 66.2 | I16: =I17+I21+I27+I43+I60+I65+I69 -> #REF! | J16: =J17+J21+J27+J43+J60+J65+J69 -> #REF! | K16: =K17+K21+K27+K43+K60+K65+K69 -> #REF!
B17: A | C17: PENGALAMAN | E17: =SUM(E18:E19) -> 0.1 | G17: =SUM(G18:G20) -> 6 | H17: =SUM(H18:H20) -> 4 | I17: =SUM(I18:I20) -> #REF! | J17: =SUM(J18:J20) -> #REF! | K17: =SUM(K18:K20) -> #REF!
A18: A100 | B18: 1 | C18: =VLOOKUP($A18,PERTANYAAN!$A$18:$E$71,3,0) -> Pengalaman di dalam Daniswara Group | D18: =VLOOKUP($A18,PERTANYAAN!$A$18:$E$71,4,0) -> Apakah ada Pengalaman di Daniswara Group? Bagaimana pandangan anda terkait Daniswara Group? | E18: =VLOOKUP($A18,PERTANYAAN!$A$18:$E$71,5,0) -> 0.06 | G18: =+'PENILAIAN-HR'!M18 -> 6 | H18: =+'PENILAIAN-ILHAM'!M18 -> 0 | I18: =+#REF! -> #REF! | J18: =+#REF! -> #REF! | K18: =AVERAGE(G18:J18) -> #REF!
A19: A200 | B19: =B18+1 -> 2 | C19: =VLOOKUP($A19,PERTANYAAN!$A$18:$E$71,3,0) -> Pengalaman di luar Daniswara Group | D19: =VLOOKUP($A19,PERTANYAAN!$A$18:$E$71,4,0) -> Jika tidak, apakah sudah ada pengalaman sejenis di luar Daniswara? | E19: =VLOOKUP($A19,PERTANYAAN!$A$18:$E$71,5,0) -> 0.04 | G19: =+'PENILAIAN-HR'!M19 -> 0 | H19: =+'PENILAIAN-ILHAM'!M19 -> 4 | I19: =+#REF! -> #REF! | J19: =+#REF! -> #REF! | K19: =AVERAGE(G19:J19) -> #REF!
B21: B | C21: ADMINISTRASI | E21: =SUM(E22:E25) -> 0.05 | G21: =SUM(G22:G25) -> 5 | H21: =SUM(H22:H25) -> 3 | I21: =SUM(I22:I25) -> #REF! | J21: =SUM(J22:J25) -> #REF! | K21: =SUM(K22:K25) -> #REF!
A22: B100 | B22: 1 | C22: =VLOOKUP($A22,PERTANYAAN!$A$18:$E$71,3,0) -> Identitas (KTP & KK) | D22: =VLOOKUP($A22,PERTANYAAN!$A$18:$E$71,4,0) -> Apakah ada Identitas Diri KTP & KK? | E22: =VLOOKUP($A22,PERTANYAAN!$A$18:$E$71,5,0) -> 0.01 | G22: =+'PENILAIAN-HR'!M22 -> 1 | H22: =+'PENILAIAN-ILHAM'!M22 -> 1 | I22: =+#REF! -> #REF! | J22: =+#REF! -> #REF! | K22: =AVERAGE(G22:J22) -> #REF!
A23: B200 | B23: =B22+1 -> 2 | C23: =VLOOKUP($A23,PERTANYAAN!$A$18:$E$71,3,0) -> SIM A (utk jabatan di Divisi Operasi) | D23: =VLOOKUP($A23,PERTANYAAN!$A$18:$E$71,4,0) -> Apakah sudah memiliki SIM A? | E23: =VLOOKUP($A23,PERTANYAAN!$A$18:$E$71,5,0) -> 0.02 | G23: =+'PENILAIAN-HR'!M23 -> 2 | H23: =+'PENILAIAN-ILHAM'!M23 -> 0 | I23: =+#REF! -> #REF! | J23: =+#REF! -> #REF! | K23: =AVERAGE(G23:J23) -> #REF!
A24: B300 | B24: =B23+1 -> 3 | C24: =VLOOKUP($A24,PERTANYAAN!$A$18:$E$71,3,0) -> SIM C | D24: =VLOOKUP($A24,PERTANYAAN!$A$18:$E$71,4,0) -> Apakah sudah memiliki SIM C? | E24: =VLOOKUP($A24,PERTANYAAN!$A$18:$E$71,5,0) -> 0.01 | G24: =+'PENILAIAN-HR'!M24 -> 1 | H24: =+'PENILAIAN-ILHAM'!M24 -> 1 | I24: =+#REF! -> #REF! | J24: =+#REF! -> #REF! | K24: =AVERAGE(G24:J24) -> #REF!
A25: B400 | B25: =B24+1 -> 4 | C25: =VLOOKUP($A25,PERTANYAAN!$A$18:$E$71,3,0) -> NPWP | D25: =VLOOKUP($A25,PERTANYAAN!$A$18:$E$71,4,0) -> Apakah sudah Memiliki NPWP? | E25: =VLOOKUP($A25,PERTANYAAN!$A$18:$E$71,5,0) -> 0.01 | G25: =+'PENILAIAN-HR'!M25 -> 1 | H25: =+'PENILAIAN-ILHAM'!M25 -> 1 | I25: =+#REF! -> #REF! | J25: =+#REF! -> #REF! | K25: =AVERAGE(G25:J25) -> #REF!
B27: C | C27: HARD SKILL | E27: =E28 -> 0.35 | G27: =G28 -> 23 | H27: =H28 -> 20 | I27: =I28 -> #REF! | J27: =J28 -> #REF! | K27: =K28 -> #REF!
A28: C100 | B28: 1 | C28: =VLOOKUP($A28,PERTANYAAN!$A$18:$E$71,3,0) -> Operasi / Logistik | E28: =VLOOKUP($A28,PERTANYAAN!$A$18:$E$71,5,0) -> 0.35 | G28: =SUM(G29:G33) -> 23 | H28: =SUM(H29:H33) -> 20 | I28: =SUM(I29:I33) -> #REF! | J28: =SUM(J29:J33) -> #REF! | K28: =SUM(K29:K33) -> #REF!
A29: C110 | B29: - | C29: =VLOOKUP($A29,PERTANYAAN!$A$18:$E$71,3,0) -> Skill Mengemudi | D29: =VLOOKUP($A29,PERTANYAAN!$A$18:$E$71,4,0) -> Coba ceritakan pengalaman / keahlian dalam mengemudi mobil angkut/logistik? | E29: =VLOOKUP($A29,PERTANYAAN!$A$18:$E$71,5,0) -> 0.15 | G29: =+'PENILAIAN-HR'!M29 -> 12 | H29: =+'PENILAIAN-ILHAM'!M29 -> 6 | I29: =+#REF! -> #REF! | J29: =+#REF! -> #REF! | K29: =AVERAGE(G29:J29) -> #REF!
A30: C120 | B30: - | C30: =VLOOKUP($A30,PERTANYAAN!$A$18:$E$71,3,0) -> Flow Administrasi Logistik | D30: =VLOOKUP($A30,PERTANYAAN!$A$18:$E$71,4,0) -> Coba ceritakan yang anda ketahui tentang alur administrasi logistik? Dan kaitannya dengan Ms. Office | E30: =VLOOKUP($A30,PERTANYAAN!$A$18:$E$71,5,0) -> 0.1 | G30: =+'PENILAIAN-HR'!M30 -> 6 | H30: =+'PENILAIAN-ILHAM'!M30 -> 6 | I30: =+#REF! -> #REF! | J30: =+#REF! -> #REF! | K30: =AVERAGE(G30:J30) -> #REF!
A31: C130 | B31: - | C31: =VLOOKUP($A31,PERTANYAAN!$A$18:$E$71,3,0) -> Pengetahuan terkait logistik | D31: =VLOOKUP($A31,PERTANYAAN!$A$18:$E$71,4,0) -> Ceritakan yang anda ketahui terkait dengan logistik? | E31: =VLOOKUP($A31,PERTANYAAN!$A$18:$E$71,5,0) -> 0.025 | G31: =+'PENILAIAN-HR'!M31 -> 2 | H31: =+'PENILAIAN-ILHAM'!M31 -> 2 | I31: =+#REF! -> #REF! | J31: =+#REF! -> #REF! | K31: =AVERAGE(G31:J31) -> #REF!
A32: C140 | B32: - | C32: =VLOOKUP($A32,PERTANYAAN!$A$18:$E$71,3,0) -> Pengalaman di Bongkar Muat | D32: =VLOOKUP($A32,PERTANYAAN!$A$18:$E$71,4,0) -> Apakah memiliki pengalaman terkait bongkar muat?sedalam apa? | E32: =VLOOKUP($A32,PERTANYAAN!$A$18:$E$71,5,0) -> 0.075 | G32: =+'PENILAIAN-HR'!M32 -> 3 | H32: =+'PENILAIAN-ILHAM'!M32 -> 6 | I32: =+#REF! -> #REF! | J32: =+#REF! -> #REF! | K32: =AVERAGE(G32:J32) -> #REF!
B34: =B28+1 -> 2 | C34: Keuangan | E34: =SUM(E35:E37) -> 0.35
B35: - | C35: Skill Akuntansi & Input Data | E35: 0.15
B36: - | C36: Microsoft Office | E36: 0.2
B38: 3 | C38: Busdev & HR
B39: - | C39: Pengalaman Kreatif
B40: - | C40: Organisasi Perusahaan & Lembaga
B41: -
B43: D | C43: SOFT SKILL | E43: =E44 -> 0.25 | G43: =G44 -> 18 | H43: =H44 -> 21 | I43: =I44 -> #REF! | J43: =J44 -> #REF! | K43: =K44 -> #REF!
A44: D100 | B44: 1 | C44: =VLOOKUP($A44,PERTANYAAN!$A$18:$E$71,3,0) -> Staff | E44: =SUM(E45:E49) -> 0.25 | G44: =SUM(G45:G48) -> 18 | H44: =SUM(H45:H48) -> 21 | I44: =SUM(I45:I48) -> #REF! | J44: =SUM(J45:J48) -> #REF! | K44: =SUM(K45:K48) -> #REF!
A45: D110 | B45: - | C45: =VLOOKUP($A45,PERTANYAAN!$A$18:$E$71,3,0) -> Kepemimpinan | D45: =VLOOKUP($A45,PERTANYAAN!$A$18:$E$71,4,0) -> Jika terjadi suatu diskusi dalam group/kelompok yang belum menemukan titik temu, apa yang akan anda lakukan? | E45: =VLOOKUP($A45,PERTANYAAN!$A$18:$E$71,5,0) -> 0.025 | G45: =+'PENILAIAN-HR'!M45 -> 1 | H45: =+'PENILAIAN-ILHAM'!M45 -> 1.5 | I45: =+#REF! -> #REF! | J45: =+#REF! -> #REF! | K45: =AVERAGE(G45:J45) -> #REF!
A46: D120 | B46: - | C46: =VLOOKUP($A46,PERTANYAAN!$A$18:$E$71,3,0) -> Komunikasi | D46: =VLOOKUP($A46,PERTANYAAN!$A$18:$E$71,4,0) -> Bagaimana hubungan kerjasama antar sesama pegawai / organisasi / kelompok?(jika memiliki pengalaman kerja) | E46: =VLOOKUP($A46,PERTANYAAN!$A$18:$E$71,5,0) -> 0.1 | G46: =+'PENILAIAN-HR'!M46 -> 6 | H46: =+'PENILAIAN-ILHAM'!M46 -> 8 | I46: =+#REF! -> #REF! | J46: =+#REF! -> #REF! | K46: =AVERAGE(G46:J46) -> #REF!
A47: D130 | B47: - | C47: =VLOOKUP($A47,PERTANYAAN!$A$18:$E$71,3,0) -> Patuh pada Peraturan / Commitment | D47: =VLOOKUP($A47,PERTANYAAN!$A$18:$E$71,4,0) -> Bagaimana pandangan anda terkait perusahaan dan aturan yang dapat berubah ubah sesuai arah perusahaan? | E47: =VLOOKUP($A47,PERTANYAAN!$A$18:$E$71,5,0) -> 0.05 | G47: =+'PENILAIAN-HR'!M47 -> 5 | H47: =+'PENILAIAN-ILHAM'!M47 -> 4 | I47: =+#REF! -> #REF! | J47: =+#REF! -> #REF! | K47: =AVERAGE(G47:J47) -> #REF!
A48: D140 | B48: - | C48: =VLOOKUP($A48,PERTANYAAN!$A$18:$E$71,3,0) -> Determinasi thd tekanan | D48: =VLOOKUP($A48,PERTANYAAN!$A$18:$E$71,4,0) -> Bagaimana pandangan anda jika anda dituntut pada pekerjaan diluar dari waktu normal dalam bekerja? | E48: =VLOOKUP($A48,PERTANYAAN!$A$18:$E$71,5,0) -> 0.075 | G48: =+'PENILAIAN-HR'!M48 -> 6 | H48: =+'PENILAIAN-ILHAM'!M48 -> 7.5 | I48: =+#REF! -> #REF! | J48: =+#REF! -> #REF! | K48: =AVERAGE(G48:J48) -> #REF!
B50: 2 | C50: Supervisor
...

Sheet PENILAIAN-HR
A1: FORM PENILAIAN PEGAWAI & CALON PEGAWAI
A2: DANISWARA GROUP
A5: NAMA | B5: : | C5: DENY FERDIANSYAH | L5: KETERANGAN
A6: POSISI PELAMAR | B6: : | C6: STAFF OPERASI | L6: SK | M6: : | N6: SANGAT KURANG
A7: PENEMPATAN | B7: : | C7: IKN - KALIMANTAN TIMUR | L7: K | M7: : | N7: KURANG
A8: DIVISI | B8: : | C8: OPERASI | L8: R | M8: : | N8: RATA-RATA
A9: BUDGET SALARY | B9: : | C9: RANGE 4 JT - 4,8 JT (ALL IN - IKN) | L9: B | M9: : | N9: BAIK
A10: PENILAI | B10: : | C10: ANGGY PERMANA PUTRA | D10: (HR) | L10: SB | M10: : | N10: SANGAT BAIK
A11: HASIL PENILAIAN | B11: : | C11: =M16 -> 70.8
A13: KODE ACC | B13: NO. | C13: KATEGORI | D13: BOBOT | F13: CHECK | H13: PENILAIAN | M13: HASIL | N13: KETERANGAN
F14: ADA | G14: TIDAK | H14: SK | I14: K | J14: R | K14: B | L14: SB
H15: 0.2 | I15: 0.4 | J15: 0.6 | K15: 0.8 | L15: 1
C16: GRAND TOTAL PENILAIAN | M16: =M17+M21+M27+M43+M60+M65+M69 -> 70.8
B17: A | C17: PENGALAMAN (jika ada) | D17: =SUM(D18:D19) -> 0.1 | M17: =SUM(M18:M20) -> 6
A18: A100 | B18: 1 | C18: =VLOOKUP($A18,PERTANYAAN!$A$18:$E$71,3,0) -> Pengalaman di dalam Daniswara Group | D18: =VLOOKUP($A18,PERTANYAAN!$A$18:$E$71,5,0) -> 0.06 | F18: V | M18: =IF(F18="V",D18*100,0) -> 6
A19: A200 | B19: =B18+1 -> 2 | C19: =VLOOKUP($A19,PERTANYAAN!$A$18:$E$71,3,0) -> Pengalaman di luar Daniswara Group | D19: =VLOOKUP($A19,PERTANYAAN!$A$18:$E$71,5,0) -> 0.04 | G19: V | M19: =IF(F19="V",D19*100,0) -> 0
B21: B | C21: ADMINISTRASI | D21: =SUM(D22:D25) -> 0.05 | M21: =SUM(M22:M25) -> 5
A22: B100 | B22: 1 | C22: =VLOOKUP($A22,PERTANYAAN!$A$18:$E$71,3,0) -> Identitas (KTP & KK) | D22: =VLOOKUP($A22,PERTANYAAN!$A$18:$E$71,5,0) -> 0.01 | F22: V | M22: =IF(F22="V",D22*100,0) -> 1
A23: B200 | B23: =B22+1 -> 2 | C23: =VLOOKUP($A23,PERTANYAAN!$A$18:$E$71,3,0) -> SIM A (utk jabatan di Divisi Operasi) | D23: =VLOOKUP($A23,PERTANYAAN!$A$18:$E$71,5,0) -> 0.02 | F23: V | M23: =IF(F23="V",D23*100,0) -> 2
A24: B300 | B24: =B23+1 -> 3 | C24: =VLOOKUP($A24,PERTANYAAN!$A$18:$E$71,3,0) -> SIM C | D24: =VLOOKUP($A24,PERTANYAAN!$A$18:$E$71,5,0) -> 0.01 | F24: V | M24: =IF(F24="V",D24*100,0) -> 1
A25: B400 | B25: =B24+1 -> 4 | C25: =VLOOKUP($A25,PERTANYAAN!$A$18:$E$71,3,0) -> NPWP | D25: =VLOOKUP($A25,PERTANYAAN!$A$18:$E$71,5,0) -> 0.01 | F25: V | M25: =IF(F25="V",D25*100,0) -> 1
B27: C | C27: HARD SKILL | D27: =D28 -> 0.35 | M27: =M28 -> 23
A28: C100 | B28: 1 | C28: =VLOOKUP($A28,PERTANYAAN!$A$18:$E$71,3,0) -> Operasi / Logistik | D28: =VLOOKUP($A28,PERTANYAAN!$A$18:$E$71,5,0) -> 0.35 | M28: =SUM(M29:M33) -> 23
A29: C110 | B29: - | C29: =VLOOKUP($A29,PERTANYAAN!$A$18:$E$71,3,0) -> Skill Mengemudi | D29: =VLOOKUP($A29,PERTANYAAN!$A$18:$E$71,5,0) -> 0.15 | K29: V | M29: =IF(H29="V",$D29*H$15,IF(I29="V",$D29*I$15,IF(J29="V",$D29*J$15,IF(K29="V",$D29*K$15,IF(L29="V",$D29*L$15,0)))))*100 -> 12
A30: C120 | B30: - | C30: =VLOOKUP($A30,PERTANYAAN!$A$18:$E$71,3,0) -> Flow Administrasi Logistik | D30: =VLOOKUP($A30,PERTANYAAN!$A$18:$E$71,5,0) -> 0.1 | J30: V | M30: =IF(H30="V",$D30*H$15,IF(I30="V",$D30*I$15,IF(J30="V",$D30*J$15,IF(K30="V",$D30*K$15,IF(L30="V",$D30*L$15,0)))))*100 -> 6
A31: C130 | B31: - | C31: =VLOOKUP($A31,PERTANYAAN!$A$18:$E$71,3,0) -> Pengetahuan terkait logistik | D31: =VLOOKUP($A31,PERTANYAAN!$A$18:$E$71,5,0) -> 0.025 | K31: V | M31: =IF(H31="V",$D31*H$15,IF(I31="V",$D31*I$15,IF(J31="V",$D31*J$15,IF(K31="V",$D31*K$15,IF(L31="V",$D31*L$15,0)))))*100 -> 2
A32: C140 | B32: - | C32: =VLOOKUP($A32,PERTANYAAN!$A$18:$E$71,3,0) -> Pengalaman di Bongkar Muat | D32: =VLOOKUP($A32,PERTANYAAN!$A$18:$E$71,5,0) -> 0.075 | I32: V | M32: =IF(H32="V",$D32*H$15,IF(I32="V",$D32*I$15,IF(J32="V",$D32*J$15,IF(K32="V",$D32*K$15,IF(L32="V",$D32*L$15,0)))))*100 -> 3
B34: =B28+1 -> 2 | C34: Keuangan | D34: =SUM(D35:D37) -> 0.35
B35: - | C35: Skill Akuntansi & Input Data | D35: 0.15
B36: - | C36: Microsoft Office | D36: 0.2
B38: 3 | C38: Busdev & HR
B39: - | C39: Pengalaman Kreatif
B40: - | C40: Organisasi Perusahaan & Lembaga
B41: -
B43: D | C43: SOFT SKILL | D43: =D44 -> 0.25 | M43: =M44 -> 18
A44: D100 | B44: 1 | C44: =VLOOKUP($A44,PERTANYAAN!$A$18:$E$71,3,0) -> Staff | D44: =VLOOKUP($A44,PERTANYAAN!$A$18:$E$71,5,0) -> 0.25 | M44: =SUM(M45:M48) -> 18
A45: D110 | B45: - | C45: =VLOOKUP($A45,PERTANYAAN!$A$18:$E$71,3,0) -> Kepemimpinan | D45: =VLOOKUP($A45,PERTANYAAN!$A$18:$E$71,5,0) -> 0.025 | I45: V | M45: =IF(H45="V",$D45*H$15,IF(I45="V",$D45*I$15,IF(J45="V",$D45*J$15,IF(K45="V",$D45*K$15,IF(L45="V",$D45*L$15,0)))))*100 -> 1
A46: D120 | B46: - | C46: =VLOOKUP($A46,PERTANYAAN!$A$18:$E$71,3,0) -> Komunikasi | D46: =VLOOKUP($A46,PERTANYAAN!$A$18:$E$71,5,0) -> 0.1 | J46: V | M46: =IF(H46="V",$D46*H$15,IF(I46="V",$D46*I$15,IF(J46="V",$D46*J$15,IF(K46="V",$D46*K$15,IF(L46="V",$D46*L$15,0)))))*100 -> 6
A47: D130 | B47: - | C47: =VLOOKUP($A47,PERTANYAAN!$A$18:$E$71,3,0) -> Patuh pada Peraturan / Commitment | D47: =VLOOKUP($A47,PERTANYAAN!$A$18:$E$71,5,0) -> 0.05 | L47: V | M47: =IF(H47="V",$D47*H$15,IF(I47="V",$D47*I$15,IF(J47="V",$D47*J$15,IF(K47="V",$D47*K$15,IF(L47="V",$D47*L$15,0)))))*100 -> 5
A48: D140 | B48: - | C48: =VLOOKUP($A48,PERTANYAAN!$A$18:$E$71,3,0) -> Determinasi thd tekanan | D48: =VLOOKUP($A48,PERTANYAAN!$A$18:$E$71,5,0) -> 0.075 | K48: V | M48: =IF(H48="V",$D48*H$15,IF(I48="V",$D48*I$15,IF(J48="V",$D48*J$15,IF(K48="V",$D48*K$15,IF(L48="V",$D48*L$15,0)))))*100 -> 6
...

Sheet PENILAIAN-ILHAM
A1: FORM PENILAIAN PEGAWAI & CALON PEGAWAI
A2: DANISWARA GROUP
A5: NAMA | B5: : | C5: ILHAM AMBIA PUTRA
A6: POSISI PELAMAR | B6: : | C6: STAFF OPERASI
A7: PENEMPATAN | B7: : | C7: DKI JAKARTA
A8: DIVISI | B8: : | C8: OPERASI
A9: BUDGET SALARY | B9: :
A10: PENILAI | B10: : | C10: WAHYU M. PUNGKI | D10: (USER)
A11: HASIL PENILAIAN | B11: : | C11: =M16 -> 66.2
A13: KODE ACC | B13: NO. | C13: KATEGORI | D13: BOBOT | F13: CHECK | H13: PENILAIAN | M13: HASIL | N13: KETERANGAN
F14: ADA | G14: TIDAK | H14: SK | I14: K | J14: R | K14: B | L14: SB
H15: 0.2 | I15: 0.4 | J15: 0.6 | K15: 0.8 | L15: 1
C16: GRAND TOTAL PENILAIAN | M16: =M17+M21+M27+M43+M60+M65+M69 -> 66.2
B17: A | C17: PENGALAMAN (jika ada) | D17: =SUM(D18:D19) -> 0.1 | M17: =SUM(M18:M20) -> 4
A18: A100 | B18: 1 | C18: =VLOOKUP($A18,PERTANYAAN!$A$18:$E$71,3,0) -> Pengalaman di dalam Daniswara Group | D18: =VLOOKUP($A18,PERTANYAAN!$A$18:$E$71,5,0) -> 0.06 | G18: V | M18: =IF(F18="V",D18*100,0) -> 0
A19: A200 | B19: =B18+1 -> 2 | C19: =VLOOKUP($A19,PERTANYAAN!$A$18:$E$71,3,0) -> Pengalaman di luar Daniswara Group | D19: =VLOOKUP($A19,PERTANYAAN!$A$18:$E$71,5,0) -> 0.04 | F19: V | M19: =IF(F19="V",D19*100,0) -> 4
B21: B | C21: ADMINISTRASI | D21: =SUM(D22:D25) -> 0.05 | M21: =SUM(M22:M25) -> 3
A22: B100 | B22: 1 | C22: =VLOOKUP($A22,PERTANYAAN!$A$18:$E$71,3,0) -> Identitas (KTP & KK) | D22: =VLOOKUP($A22,PERTANYAAN!$A$18:$E$71,5,0) -> 0.01 | F22: V | M22: =IF(F22="V",D22*100,0) -> 1
A23: B200 | B23: =B22+1 -> 2 | C23: =VLOOKUP($A23,PERTANYAAN!$A$18:$E$71,3,0) -> SIM A (utk jabatan di Divisi Operasi) | D23: =VLOOKUP($A23,PERTANYAAN!$A$18:$E$71,5,0) -> 0.02 | G23: V | M23: =IF(F23="V",D23*100,0) -> 0
A24: B300 | B24: =B23+1 -> 3 | C24: =VLOOKUP($A24,PERTANYAAN!$A$18:$E$71,3,0) -> SIM C | D24: =VLOOKUP($A24,PERTANYAAN!$A$18:$E$71,5,0) -> 0.01 | F24: V | M24: =IF(F24="V",D24*100,0) -> 1
A25: B400 | B25: =B24+1 -> 4 | C25: =VLOOKUP($A25,PERTANYAAN!$A$18:$E$71,3,0) -> NPWP | D25: =VLOOKUP($A25,PERTANYAAN!$A$18:$E$71,5,0) -> 0.01 | F25: V | M25: =IF(F25="V",D25*100,0) -> 1
B27: C | C27: HARD SKILL | D27: =D28 -> 0.35 | M27: =M28 -> 20
A28: C100 | B28: 1 | C28: =VLOOKUP($A28,PERTANYAAN!$A$18:$E$71,3,0) -> Operasi / Logistik | D28: =VLOOKUP($A28,PERTANYAAN!$A$18:$E$71,5,0) -> 0.35 | M28: =SUM(M29:M33) -> 20
A29: C110 | B29: - | C29: =VLOOKUP($A29,PERTANYAAN!$A$18:$E$71,3,0) -> Skill Mengemudi | D29: =VLOOKUP($A29,PERTANYAAN!$A$18:$E$71,5,0) -> 0.15 | I29: V | M29: =IF(H29="V",$D29*H$15,IF(I29="V",$D29*I$15,IF(J29="V",$D29*J$15,IF(K29="V",$D29*K$15,IF(L29="V",$D29*L$15,0)))))*100 -> 6
A30: C120 | B30: - | C30: =VLOOKUP($A30,PERTANYAAN!$A$18:$E$71,3,0) -> Flow Administrasi Logistik | D30: =VLOOKUP($A30,PERTANYAAN!$A$18:$E$71,5,0) -> 0.1 | J30: V | M30: =IF(H30="V",$D30*H$15,IF(I30="V",$D30*I$15,IF(J30="V",$D30*J$15,IF(K30="V",$D30*K$15,IF(L30="V",$D30*L$15,0)))))*100 -> 6
A31: C130 | B31: - | C31: =VLOOKUP($A31,PERTANYAAN!$A$18:$E$71,3,0) -> Pengetahuan terkait logistik | D31: =VLOOKUP($A31,PERTANYAAN!$A$18:$E$71,5,0) -> 0.025 | K31: V | M31: =IF(H31="V",$D31*H$15,IF(I31="V",$D31*I$15,IF(J31="V",$D31*J$15,IF(K31="V",$D31*K$15,IF(L31="V",$D31*L$15,0)))))*100 -> 2
A32: C140 | B32: - | C32: =VLOOKUP($A32,PERTANYAAN!$A$18:$E$71,3,0) -> Pengalaman di Bongkar Muat | D32: =VLOOKUP($A32,PERTANYAAN!$A$18:$E$71,5,0) -> 0.075 | K32: V | M32: =IF(H32="V",$D32*H$15,IF(I32="V",$D32*I$15,IF(J32="V",$D32*J$15,IF(K32="V",$D32*K$15,IF(L32="V",$D32*L$15,0)))))*100 -> 6
B34: =B28+1 -> 2 | C34: Keuangan | D34: =SUM(D35:D37) -> 0.35
B35: - | C35: Skill Akuntansi & Input Data | D35: 0.15
B36: - | C36: Microsoft Office | D36: 0.2
B38: 3 | C38: Busdev & HR
B39: - | C39: Pengalaman Kreatif
B40: - | C40: Organisasi Perusahaan & Lembaga
B41: -
B43: D | C43: SOFT SKILL | D43: =D44 -> 0.25 | M43: =M44 -> 21
A44: D100 | B44: 1 | C44: =VLOOKUP($A44,PERTANYAAN!$A$18:$E$71,3,0) -> Staff | D44: =VLOOKUP($A44,PERTANYAAN!$A$18:$E$71,5,0) -> 0.25 | M44: =SUM(M45:M48) -> 21
A45: D110 | B45: - | C45: =VLOOKUP($A45,PERTANYAAN!$A$18:$E$71,3,0) -> Kepemimpinan | D45: =VLOOKUP($A45,PERTANYAAN!$A$18:$E$71,5,0) -> 0.025 | J45: V | M45: =IF(H45="V",$D45*H$15,IF(I45="V",$D45*I$15,IF(J45="V",$D45*J$15,IF(K45="V",$D45*K$15,IF(L45="V",$D45*L$15,0)))))*100 -> 1.5
A46: D120 | B46: - | C46: =VLOOKUP($A46,PERTANYAAN!$A$18:$E$71,3,0) -> Komunikasi | D46: =VLOOKUP($A46,PERTANYAAN!$A$18:$E$71,5,0) -> 0.1 | K46: V | M46: =IF(H46="V",$D46*H$15,IF(I46="V",$D46*I$15,IF(J46="V",$D46*J$15,IF(K46="V",$D46*K$15,IF(L46="V",$D46*L$15,0)))))*100 -> 8
A47: D130 | B47: - | C47: =VLOOKUP($A47,PERTANYAAN!$A$18:$E$71,3,0) -> Patuh pada Peraturan / Commitment | D47: =VLOOKUP($A47,PERTANYAAN!$A$18:$E$71,5,0) -> 0.05 | K47: V | M47: =IF(H47="V",$D47*H$15,IF(I47="V",$D47*I$15,IF(J47="V",$D47*J$15,IF(K47="V",$D47*K$15,IF(L47="V",$D47*L$15,0)))))*100 -> 4
A48: D140 | B48: - | C48: =VLOOKUP($A48,PERTANYAAN!$A$18:$E$71,3,0) -> Determinasi thd tekanan | D48: =VLOOKUP($A48,PERTANYAAN!$A$18:$E$71,5,0) -> 0.075 | L48: V | M48: =IF(H48="V",$D48*H$15,IF(I48="V",$D48*I$15,IF(J48="V",$D48*J$15,IF(K48="V",$D48*K$15,IF(L48="V",$D48*L$15,0)))))*100 -> 7.5
...

Sheet PENILAIAN-DICKY
A1: FORM PENILAIAN PEGAWAI & CALON PEGAWAI
A2: DANISWARA GROUP
A5: NAMA | B5: : | C5: MOHAMAD DICKY
A6: POSISI PELAMAR | B6: : | C6: STAFF OPERASI
A7: PENEMPATAN | B7: : | C7: DKI JAKARTA
A8: DIVISI | B8: : | C8: OPERASI
A9: BUDGET SALARY | B9: :
A10: PENILAI | B10: : | C10: WAHYU M. PUNGKI | D10: (USER)
A11: HASIL PENILAIAN | B11: : | C11: =M16 -> 62.2
A13: KODE ACC | B13: NO. | C13: KATEGORI | D13: BOBOT | F13: CHECK | H13: PENILAIAN | M13: HASIL | N13: KETERANGAN
F14: ADA | G14: TIDAK | H14: SK | I14: K | J14: R | K14: B | L14: SB
H15: 0.2 | I15: 0.4 | J15: 0.6 | K15: 0.8 | L15: 1
C16: GRAND TOTAL PENILAIAN | M16: =M17+M21+M27+M43+M60+M65+M69 -> 62.2
B17: A | C17: PENGALAMAN (jika ada) | D17: =SUM(D18:D19) -> 0.1 | M17: =SUM(M18:M20) -> 0
A18: A100 | B18: 1 | C18: =VLOOKUP($A18,PERTANYAAN!$A$18:$E$71,3,0) -> Pengalaman di dalam Daniswara Group | D18: =VLOOKUP($A18,PERTANYAAN!$A$18:$E$71,5,0) -> 0.06 | G18: V | M18: =IF(F18="V",D18*100,0) -> 0
A19: A200 | B19: =B18+1 -> 2 | C19: =VLOOKUP($A19,PERTANYAAN!$A$18:$E$71,3,0) -> Pengalaman di luar Daniswara Group | D19: =VLOOKUP($A19,PERTANYAAN!$A$18:$E$71,5,0) -> 0.04 | G19: V | M19: =IF(F19="V",D19*100,0) -> 0
B21: B | C21: ADMINISTRASI | D21: =SUM(D22:D25) -> 0.05 | M21: =SUM(M22:M25) -> 3
A22: B100 | B22: 1 | C22: =VLOOKUP($A22,PERTANYAAN!$A$18:$E$71,3,0) -> Identitas (KTP & KK) | D22: =VLOOKUP($A22,PERTANYAAN!$A$18:$E$71,5,0) -> 0.01 | F22: V | M22: =IF(F22="V",D22*100,0) -> 1
A23: B200 | B23: =B22+1 -> 2 | C23: =VLOOKUP($A23,PERTANYAAN!$A$18:$E$71,3,0) -> SIM A (utk jabatan di Divisi Operasi) | D23: =VLOOKUP($A23,PERTANYAAN!$A$18:$E$71,5,0) -> 0.02 | G23: V | M23: =IF(F23="V",D23*100,0) -> 0
A24: B300 | B24: =B23+1 -> 3 | C24: =VLOOKUP($A24,PERTANYAAN!$A$18:$E$71,3,0) -> SIM C | D24: =VLOOKUP($A24,PERTANYAAN!$A$18:$E$71,5,0) -> 0.01 | F24: V | M24: =IF(F24="V",D24*100,0) -> 1
A25: B400 | B25: =B24+1 -> 4 | C25: =VLOOKUP($A25,PERTANYAAN!$A$18:$E$71,3,0) -> NPWP | D25: =VLOOKUP($A25,PERTANYAAN!$A$18:$E$71,5,0) -> 0.01 | F25: V | M25: =IF(F25="V",D25*100,0) -> 1
B27: C | C27: HARD SKILL | D27: =D28 -> 0.35 | M27: =M28 -> 17
A28: C100 | B28: 1 | C28: =VLOOKUP($A28,PERTANYAAN!$A$18:$E$71,3,0) -> Operasi / Logistik | D28: =VLOOKUP($A28,PERTANYAAN!$A$18:$E$71,5,0) -> 0.35 | M28: =SUM(M29:M33) -> 17
A29: C110 | B29: - | C29: =VLOOKUP($A29,PERTANYAAN!$A$18:$E$71,3,0) -> Skill Mengemudi | D29: =VLOOKUP($A29,PERTANYAAN!$A$18:$E$71,5,0) -> 0.15 | H29: V | M29: =IF(H29="V",$D29*H$15,IF(I29="V",$D29*I$15,IF(J29="V",$D29*J$15,IF(K29="V",$D29*K$15,IF(L29="V",$D29*L$15,0)))))*100 -> 3
A30: C120 | B30: - | C30: =VLOOKUP($A30,PERTANYAAN!$A$18:$E$71,3,0) -> Flow Administrasi Logistik | D30: =VLOOKUP($A30,PERTANYAAN!$A$18:$E$71,5,0) -> 0.1 | K30: V | M30: =IF(H30="V",$D30*H$15,IF(I30="V",$D30*I$15,IF(J30="V",$D30*J$15,IF(K30="V",$D30*K$15,IF(L30="V",$D30*L$15,0)))))*100 -> 8
A31: C130 | B31: - | C31: =VLOOKUP($A31,PERTANYAAN!$A$18:$E$71,3,0) -> Pengetahuan terkait logistik | D31: =VLOOKUP($A31,PERTANYAAN!$A$18:$E$71,5,0) -> 0.025 | J31: V | M31: =IF(H31="V",$D31*H$15,IF(I31="V",$D31*I$15,IF(J31="V",$D31*J$15,IF(K31="V",$D31*K$15,IF(L31="V",$D31*L$15,0)))))*100 -> 1.5
A32: C140 | B32: - | C32: =VLOOKUP($A32,PERTANYAAN!$A$18:$E$71,3,0) -> Pengalaman di Bongkar Muat | D32: =VLOOKUP($A32,PERTANYAAN!$A$18:$E$71,5,0) -> 0.075 | J32: V | M32: =IF(H32="V",$D32*H$15,IF(I32="V",$D32*I$15,IF(J32="V",$D32*J$15,IF(K32="V",$D32*K$15,IF(L32="V",$D32*L$15,0)))))*100 -> 4.5
B34: =B28+1 -> 2 | C34: Keuangan | D34: =SUM(D35:D37) -> 0.35
B35: - | C35: Skill Akuntansi & Input Data | D35: 0.15
B36: - | C36: Microsoft Office | D36: 0.2
B38: 3 | C38: Busdev & HR
B39: - | C39: Pengalaman Kreatif
B40: - | C40: Organisasi Perusahaan & Lembaga
B41: -
B43: D | C43: SOFT SKILL | D43: =D44 -> 0.25 | M43: =M44 -> 22.5
A44: D100 | B44: 1 | C44: =VLOOKUP($A44,PERTANYAAN!$A$18:$E$71,3,0) -> Staff | D44: =VLOOKUP($A44,PERTANYAAN!$A$18:$E$71,5,0) -> 0.25 | M44: =SUM(M45:M48) -> 22.5
A45: D110 | B45: - | C45: =VLOOKUP($A45,PERTANYAAN!$A$18:$E$71,3,0) -> Kepemimpinan | D45: =VLOOKUP($A45,PERTANYAAN!$A$18:$E$71,5,0) -> 0.025 | K45: V | M45: =IF(H45="V",$D45*H$15,IF(I45="V",$D45*I$15,IF(J45="V",$D45*J$15,IF(K45="V",$D45*K$15,IF(L45="V",$D45*L$15,0)))))*100 -> 2
A46: D120 | B46: - | C46: =VLOOKUP($A46,PERTANYAAN!$A$18:$E$71,3,0) -> Komunikasi | D46: =VLOOKUP($A46,PERTANYAAN!$A$18:$E$71,5,0) -> 0.1 | L46: V | M46: =IF(H46="V",$D46*H$15,IF(I46="V",$D46*I$15,IF(J46="V",$D46*J$15,IF(K46="V",$D46*K$15,IF(L46="V",$D46*L$15,0)))))*100 -> 10
A47: D130 | B47: - | C47: =VLOOKUP($A47,PERTANYAAN!$A$18:$E$71,3,0) -> Patuh pada Peraturan / Commitment | D47: =VLOOKUP($A47,PERTANYAAN!$A$18:$E$71,5,0) -> 0.05 | J47: V | M47: =IF(H47="V",$D47*H$15,IF(I47="V",$D47*I$15,IF(J47="V",$D47*J$15,IF(K47="V",$D47*K$15,IF(L47="V",$D47*L$15,0)))))*100 -> 3
A48: D140 | B48: - | C48: =VLOOKUP($A48,PERTANYAAN!$A$18:$E$71,3,0) -> Determinasi thd tekanan | D48: =VLOOKUP($A48,PERTANYAAN!$A$18:$E$71,5,0) -> 0.075 | L48: V | M48: =IF(H48="V",$D48*H$15,IF(I48="V",$D48*I$15,IF(J48="V",$D48*J$15,IF(K48="V",$D48*K$15,IF(L48="V",$D48*L$15,0)))))*100 -> 7.5
...

Sheet PENILAIAN-DONY
A1: FORM PENILAIAN PEGAWAI & CALON PEGAWAI
A2: DANISWARA GROUP
A5: NAMA | B5: : | C5: M. DONI WASESO
A6: POSISI PELAMAR | B6: : | C6: STAFF OPERASI
A7: PENEMPATAN | B7: : | C7: DKI JAKARTA
A8: DIVISI | B8: : | C8: OPERASI
A9: BUDGET SALARY | B9: :
A10: PENILAI | B10: : | C10: WAHYU M. PUNGKI | D10: (USER)
A11: HASIL PENILAIAN | B11: : | C11: =M16 -> 58
A13: KODE ACC | B13: NO. | C13: KATEGORI | D13: BOBOT | F13: CHECK | H13: PENILAIAN | M13: HASIL | N13: KETERANGAN
F14: ADA | G14: TIDAK | H14: SK | I14: K | J14: R | K14: B | L14: SB
H15: 0.2 | I15: 0.4 | J15: 0.6 | K15: 0.8 | L15: 1
C16: GRAND TOTAL PENILAIAN | M16: =M17+M21+M27+M43+M60+M65+M69 -> 58
B17: A | C17: PENGALAMAN (jika ada) | D17: =SUM(D18:D19) -> 0.1 | M17: =SUM(M18:M20) -> 6
A18: A100 | B18: 1 | C18: =VLOOKUP($A18,PERTANYAAN!$A$18:$E$71,3,0) -> Pengalaman di dalam Daniswara Group | D18: =VLOOKUP($A18,PERTANYAAN!$A$18:$E$71,5,0) -> 0.06 | F18: V | M18: =IF(F18="V",D18*100,0) -> 6
A19: A200 | B19: =B18+1 -> 2 | C19: =VLOOKUP($A19,PERTANYAAN!$A$18:$E$71,3,0) -> Pengalaman di luar Daniswara Group | D19: =VLOOKUP($A19,PERTANYAAN!$A$18:$E$71,5,0) -> 0.04 | G19: V | M19: =IF(F19="V",D19*100,0) -> 0
B21: B | C21: ADMINISTRASI | D21: =SUM(D22:D25) -> 0.05 | M21: =SUM(M22:M25) -> 2
A22: B100 | B22: 1 | C22: =VLOOKUP($A22,PERTANYAAN!$A$18:$E$71,3,0) -> Identitas (KTP & KK) | D22: =VLOOKUP($A22,PERTANYAAN!$A$18:$E$71,5,0) -> 0.01 | F22: V | M22: =IF(F22="V",D22*100,0) -> 1
A23: B200 | B23: =B22+1 -> 2 | C23: =VLOOKUP($A23,PERTANYAAN!$A$18:$E$71,3,0) -> SIM A (utk jabatan di Divisi Operasi) | D23: =VLOOKUP($A23,PERTANYAAN!$A$18:$E$71,5,0) -> 0.02 | G23: V | M23: =IF(F23="V",D23*100,0) -> 0
A24: B300 | B24: =B23+1 -> 3 | C24: =VLOOKUP($A24,PERTANYAAN!$A$18:$E$71,3,0) -> SIM C | D24: =VLOOKUP($A24,PERTANYAAN!$A$18:$E$71,5,0) -> 0.01 | G24: V | M24: =IF(F24="V",D24*100,0) -> 0
A25: B400 | B25: =B24+1 -> 4 | C25: =VLOOKUP($A25,PERTANYAAN!$A$18:$E$71,3,0) -> NPWP | D25: =VLOOKUP($A25,PERTANYAAN!$A$18:$E$71,5,0) -> 0.01 | F25: V | M25: =IF(F25="V",D25*100,0) -> 1
B27: C | C27: HARD SKILL | D27: =D28 -> 0.35 | M27: =M28 -> 17.5
A28: C100 | B28: 1 | C28: =VLOOKUP($A28,PERTANYAAN!$A$18:$E$71,3,0) -> Operasi / Logistik | D28: =VLOOKUP($A28,PERTANYAAN!$A$18:$E$71,5,0) -> 0.35 | M28: =SUM(M29:M33) -> 17.5
A29: C110 | B29: - | C29: =VLOOKUP($A29,PERTANYAAN!$A$18:$E$71,3,0) -> Skill Mengemudi | D29: =VLOOKUP($A29,PERTANYAAN!$A$18:$E$71,5,0) -> 0.15 | I29: V | M29: =IF(H29="V",$D29*H$15,IF(I29="V",$D29*I$15,IF(J29="V",$D29*J$15,IF(K29="V",$D29*K$15,IF(L29="V",$D29*L$15,0)))))*100 -> 6
A30: C120 | B30: - | C30: =VLOOKUP($A30,PERTANYAAN!$A$18:$E$71,3,0) -> Flow Administrasi Logistik | D30: =VLOOKUP($A30,PERTANYAAN!$A$18:$E$71,5,0) -> 0.1 | J30: V | M30: =IF(H30="V",$D30*H$15,IF(I30="V",$D30*I$15,IF(J30="V",$D30*J$15,IF(K30="V",$D30*K$15,IF(L30="V",$D30*L$15,0)))))*100 -> 6
A31: C130 | B31: - | C31: =VLOOKUP($A31,PERTANYAAN!$A$18:$E$71,3,0) -> Pengetahuan terkait logistik | D31: =VLOOKUP($A31,PERTANYAAN!$A$18:$E$71,5,0) -> 0.025 | I31: V | M31: =IF(H31="V",$D31*H$15,IF(I31="V",$D31*I$15,IF(J31="V",$D31*J$15,IF(K31="V",$D31*K$15,IF(L31="V",$D31*L$15,0)))))*100 -> 1
A32: C140 | B32: - | C32: =VLOOKUP($A32,PERTANYAAN!$A$18:$E$71,3,0) -> Pengalaman di Bongkar Muat | D32: =VLOOKUP($A32,PERTANYAAN!$A$18:$E$71,5,0) -> 0.075 | J32: V | M32: =IF(H32="V",$D32*H$15,IF(I32="V",$D32*I$15,IF(J32="V",$D32*J$15,IF(K32="V",$D32*K$15,IF(L32="V",$D32*L$15,0)))))*100 -> 4.5
B34: =B28+1 -> 2 | C34: Keuangan | D34: =SUM(D35:D37) -> 0.35
B35: - | C35: Skill Akuntansi & Input Data | D35: 0.15
B36: - | C36: Microsoft Office | D36: 0.2
B38: 3 | C38: Busdev & HR
B39: - | C39: Pengalaman Kreatif
B40: - | C40: Organisasi Perusahaan & Lembaga
B41: -
B43: D | C43: SOFT SKILL | D43: =D44 -> 0.25 | M43: =M44 -> 15
A44: D100 | B44: 1 | C44: =VLOOKUP($A44,PERTANYAAN!$A$18:$E$71,3,0) -> Staff | D44: =VLOOKUP($A44,PERTANYAAN!$A$18:$E$71,5,0) -> 0.25 | M44: =SUM(M45:M48) -> 15
A45: D110 | B45: - | C45: =VLOOKUP($A45,PERTANYAAN!$A$18:$E$71,3,0) -> Kepemimpinan | D45: =VLOOKUP($A45,PERTANYAAN!$A$18:$E$71,5,0) -> 0.025 | I45: V | M45: =IF(H45="V",$D45*H$15,IF(I45="V",$D45*I$15,IF(J45="V",$D45*J$15,IF(K45="V",$D45*K$15,IF(L45="V",$D45*L$15,0)))))*100 -> 1
A46: D120 | B46: - | C46: =VLOOKUP($A46,PERTANYAAN!$A$18:$E$71,3,0) -> Komunikasi | D46: =VLOOKUP($A46,PERTANYAAN!$A$18:$E$71,5,0) -> 0.1 | I46: V | M46: =IF(H46="V",$D46*H$15,IF(I46="V",$D46*I$15,IF(J46="V",$D46*J$15,IF(K46="V",$D46*K$15,IF(L46="V",$D46*L$15,0)))))*100 -> 4
A47: D130 | B47: - | C47: =VLOOKUP($A47,PERTANYAAN!$A$18:$E$71,3,0) -> Patuh pada Peraturan / Commitment | D47: =VLOOKUP($A47,PERTANYAAN!$A$18:$E$71,5,0) -> 0.05 | K47: V | M47: =IF(H47="V",$D47*H$15,IF(I47="V",$D47*I$15,IF(J47="V",$D47*J$15,IF(K47="V",$D47*K$15,IF(L47="V",$D47*L$15,0)))))*100 -> 4
A48: D140 | B48: - | C48: =VLOOKUP($A48,PERTANYAAN!$A$18:$E$71,3,0) -> Determinasi thd tekanan | D48: =VLOOKUP($A48,PERTANYAAN!$A$18:$E$71,5,0) -> 0.075 | K48: V | M48: =IF(H48="V",$D48*H$15,IF(I48="V",$D48*I$15,IF(J48="V",$D48*J$15,IF(K48="V",$D48*K$15,IF(L48="V",$D48*L$15,0)))))*100 -> 6
...
