Workbook

Sheet PERTANYAAN
A1: FORM PENILAIAN PEGAWAI & CALON PEGAWAI
A2: DANISWARA GROUP
A5: NAMA | B5: :
A6: POSISI PELAMAR | B6: : | C6: STAFF OPERASI
A7: PENEMPATAN | B7: : | C7: IKN - KALIMANTAN TIMUR
A8: DIVISI | B8: : | C8: OPERASI
A9: BUDGET SALARY | B9: : | C9: RANGE 4 JT - 4,8 JT (ALL IN - IKN)
A10: HR | B10: : | C10: ANGGY PERMANA PUTRA
A11: HASIL PENILAIAN | B11: : | C11: =N16 -> 86.7
A13: KODE ACC | B13: NO. | C13: KATEGORI | D13: PERTANYAAN | E13: BOBOT | G13: CHECK | I13: PENILAIAN | N13: HASIL | O13: KETERANGAN
G14: ADA | H14: TIDAK | I14: SK | J14: K | K14: R | L14: B | M14: SB
A15: 1 | B15: =A15+1 -> 2 | C15: =B15+1 -> 3 | D15: =C15+1 -> 4 | E15: =D15+1 -> 5 | I15: 0.2 | J15: 0.4 | K15: 0.6 | L15: 0.8 | M15: 1
C16: GRAND TOTAL PENILAIAN | E16: =E17+E21+E27+E43+E60+E65+E69 -> 1 | N16: =N17+N21+N27+N43+N60+N65+N69 -> 86.7
B17: A | C17: PENGALAMAN | E17: =SUM(E18:E19) -> 0.1 | N17: =SUM(N18:N20) -> 10
A18: A100 | B18: 1 | C18: Pengalaman di dalam Daniswara Group | D18: Apakah ada Pengalaman di Daniswara Group? Bagaimana pandangan anda terkait Daniswara Group? | E18: 0.06 | G18: V | N18: =IF(G18="V",E18*100,0) -> 6
A19: A200 | B19: =B18+1 -> 2 | C19: Pengalaman di luar Daniswara Group | D19: Jika tidak, apakah sudah ada pengalaman sejenis di luar Daniswara? | E19: 0.04 | G19: V | N19: =IF(G19="V",E19*100,0) -> 4
B21: B | C21: ADMINISTRASI | E21: =SUM(E22:E25) -> 0.05 | N21: =SUM(N22:N25) -> 5
A22: B100 | B22: 1 | C22: Identitas (KTP & KK) | D22: Apakah ada Identitas Diri KTP & KK? | E22: 0.01 | G22: V | N22: =IF(G22="V",E22*100,0) -> 1
A23: B200 | B23: =B22+1 -> 2 | C23: SIM A (utk jabatan di Divisi Operasi) | D23: Apakah sudah memiliki SIM A? | E23: 0.02 | G23: V | N23: =IF(G23="V",E23*100,0) -> 2
A24: B300 | B24: =B23+1 -> 3 | C24: SIM C | D24: Apakah sudah memiliki SIM C? | E24: 0.01 | G24: V | N24: =IF(G24="V",E24*100,0) -> 1
A25: B400 | B25: =B24+1 -> 4 | C25: NPWP | D25: Apakah sudah Memiliki NPWP? | E25: 0.01 | G25: V | N25: =IF(G25="V",E25*100,0) -> 1
B27: C | C27: HARD SKILL | E27: =E28 -> 0.35 | N27: =N28 -> 28.5
A28: C100 | B28: 1 | C28: Operasi / Logistik | E28: =SUM(E29:E32) -> 0.35 | N28: =SUM(N29:N33) -> 28.5
A29: C110 | B29: - | C29: Skill Mengemudi | D29: Coba ceritakan pengalaman / keahlian dalam mengemudi mobil angkut/logistik? | E29: 0.15 | L29: V | N29: =IF(I29="V",$E29*I$15,IF(J29="V",$E29*J$15,IF(K29="V",$E29*K$15,IF(L29="V",$E29*L$15,IF(M29="V",$E29*M$15,0)))))*100 -> 12
A30: C120 | B30: - | C30: Flow Administrasi Logistik | D30: Coba ceritakan yang anda ketahui tentang alur administrasi logistik? Dan kaitannya dengan Ms. Office | E30: 0.1 | M30: V | N30: =IF(I30="V",$E30*I$15,IF(J30="V",$E30*J$15,IF(K30="V",$E30*K$15,IF(L30="V",$E30*L$15,IF(M30="V",$E30*M$15,0)))))*100 -> 10
A31: C130 | B31: - | C31: Pengetahuan terkait logistik | D31: Ceritakan yang anda ketahui terkait dengan logistik? | E31: 0.025 | L31: V | N31: =IF(I31="V",$E31*I$15,IF(J31="V",$E31*J$15,IF(K31="V",$E31*K$15,IF(L31="V",$E31*L$15,IF(M31="V",$E31*M$15,0)))))*100 -> 2
A32: C140 | B32: - | C32: Pengalaman di Bongkar Muat | D32: Apakah memiliki pengalaman terkait bongkar muat?sedalam apa? | E32: 0.075 | K32: V | N32: =IF(I32="V",$E32*I$15,IF(J32="V",$E32*J$15,IF(K32="V",$E32*K$15,IF(L32="V",$E32*L$15,IF(M32="V",$E32*M$15,0)))))*100 -> 4.5
B34: =B28+1 -> 2 | C34: Keuangan | E34: =SUM(E35:E37) -> 0.35
B35: - | C35: Skill Akuntansi & Input Data | E35: 0.15
B36: - | C36: Microsoft Office | E36: 0.2
B38: 3 | C38: Busdev & HR
B39: - | C39: Pengalaman Kreatif
B40: - | C40: Organisasi Perusahaan & Lembaga
B41: -
B43: D | C43: SOFT SKILL | E43: =E44 -> 0.25 | N43: =N44 -> 22.5
A44: D100 | B44: 1 | C44: Staff | E44: =SUM(E45:E49) -> 0.25 | N44: =SUM(N45:N48) -> 22.5
A45: D110 | B45: - | C45: Kepemimpinan | D45: Jika terjadi suatu diskusi dalam group/kelompok yang belum menemukan titik temu, apa yang akan anda lakukan? | E45: 0.025 | L45: V | N45: =IF(I45="V",$E45*I$15,IF(J45="V",$E45*J$15,IF(K45="V",$E45*K$15,IF(L45="V",$E45*L$15,IF(M45="V",$E45*M$15,0)))))*100 -> 2
A46: D120 | B46: - | C46: Komunikasi | D46: Bagaimana hubungan kerjasama antar sesama pegawai / organisasi / kelompok?(jika memiliki pengalaman kerja) | E46: 0.1 | L46: V | N46: =IF(I46="V",$E46*I$15,IF(J46="V",$E46*J$15,IF(K46="V",$E46*K$15,IF(L46="V",$E46*L$15,IF(M46="V",$E46*M$15,0)))))*100 -> 8
A47: D130 | B47: - | C47: Patuh pada Peraturan / Commitment | D47: Bagaimana pandangan anda terkait perusahaan dan aturan yang dapat berubah ubah sesuai arah perusahaan? | E47: 0.05 | M47: V | N47: =IF(I47="V",$E47*I$15,IF(J47="V",$E47*J$15,IF(K47="V",$E47*K$15,IF(L47="V",$E47*L$15,IF(M47="V",$E47*M$15,0)))))*100 -> 5
A48: D140 | B48: - | C48: Determinasi thd tekanan | D48: Bagaimana pandangan anda jika anda dituntut pada pekerjaan diluar dari waktu normal dalam bekerja? | E48: 0.075 | M48: V | N48: =IF(I48="V",$E48*I$15,IF(J48="V",$E48*J$15,IF(K48="V",$E48*K$15,IF(L48="V",$E48*L$15,IF(M48="V",$E48*M$15,0)))))*100 -> 7.5
...

Sheet REKAP
A1: FORM PENILAIAN PEGAWAI & CALON PEGAWAI
A2: DANISWARA GROUP
B4: REKAP HASIL PENILAIAN PEGAWAI & CALON PEGAWAI
B6: NO. | C6: NAMA PERSONIL | D6: JABATAN / CALON POSISI | E6: PENILAIAN | I6: HASIL | J6: KETERANGAN | K6: CATATAN
E7: HR | F7: USER-DJP | G7: USER-GAS | H7: MANAGER
B9: 1 | C9: DIAN YUSUF | D9: STAFF OPERASI - DKI | E9: ='HASIL-DIAN'!G16 -> 90.5 | F9: ='HASIL-DIAN'!H16 -> 88 | H9: ='HASIL-DIAN'!J16 -> 75.7 | I9: ='HASIL-DIAN'!K16 -> 86.233333 | J9: =IF(I9>=70,"LULUS",IF(I9>=60,"LULUS DENGAN CATATAN",IF(I9<60,"TIDAK LULUS",0))) -> LULUS | K9: SIM A & C Belum ada
B10: =B9+1 -> 2 | C10: DENY FERDIANSYAH | D10: STAFF OPERASI - IKN | E10: ='HASIL-DENY'!G16 -> 88 | F10: ='HASIL-DENY'!H16 -> 86 | G10: ='HASIL-DENY'!I16 -> 83 | H10: ='HASIL-DENY'!J16 -> 77 | I10: ='HASIL-DENY'!K16 -> 84.75 | J10: =IF(I10>=70,"LULUS",IF(I10>=60,"LULUS DENGAN CATATAN",IF(I10<60,"TIDAK LULUS",0))) -> LULUS | K10: SIM A Belum ada
B11: =B10+1 -> 3 | C11: IMAN | D11: STAFF OPERASI - IKN | E11: ='HASIL-IMAN'!G16 -> 79.7 | F11: ='HASIL-IMAN'!H16 -> 81.9 | G11: ='HASIL-IMAN'!I16 -> 78.6 | H11: ='HASIL-IMAN'!J16 -> 67.2 | I11: ='HASIL-IMAN'!K16 -> 77.933333 | J11: =IF(I11>=70,"LULUS",IF(I11>=60,"LULUS DENGAN CATATAN",IF(I11<60,"TIDAK LULUS",0))) -> LULUS | K11: SIM C Belum ada
B12: =B11+1 -> 4 | C12: TAUFIK HIDAYATULLAH | D12: STAFF OPERASI - IKN | E12: ='HASIL-OPIK'!G16 -> 91 | F12: ='HASIL-OPIK'!H16 -> 70 | G12: ='HASIL-OPIK'!I16 -> 81.5 | H12: ='HASIL-OPIK'!J16 -> 64.3 | I12: ='HASIL-OPIK'!K16 -> 77.616667 | J12: =IF(I12>=70,"LULUS",IF(I12>=60,"LULUS DENGAN CATATAN",IF(I12<60,"TIDAK LULUS",0))) -> LULUS | K12: SIM A Belum ada
B13: =B12+1 -> 5 | C13: SADAM | D13: STAFF OPERASI - IKN | E13: ='HASIL-SADAM'!G16 -> 48.7 | F13: ='HASIL-SADAM'!H16 -> 57.5 | G13: ='HASIL-SADAM'!I16 -> 59 | H13: ='HASIL-SADAM'!J16 -> 60.9 | I13: ='HASIL-SADAM'!K16 -> 57.525 | J13: =IF(I13>=70,"LULUS",IF(I13>=60,"LULUS DENGAN CATATAN",IF(I13<60,"TIDAK LULUS",0))) -> TIDAK LULUS

Sheet HASIL-SADAM
A1: FORM PENILAIAN PEGAWAI & CALON PEGAWAI
A2: DANISWARA GROUP
A5: NAMA | B5: : | C5: SADAM
A6: POSISI PELAMAR | B6: : | C6: STAFF OPERASI
A7: PENEMPATAN | B7: : | C7: IKN - KALIMANTAN TIMUR
A8: DIVISI | B8: : | C8: OPERASI
A9: BUDGET SALARY | B9: : | C9: RANGE 4 JT - 4,8 JT (ALL IN - IKN)
A10: HR | B10: : | C10: ANGGY PERMANA PUTRA
A11: HASIL PENILAIAN | B11: : | C11: =K16 -> 57.525
A13: KODE ACC | B13: NO. | C13: KATEGORI | D13: PERTANYAAN | E13: BOBOT | G13: PENILAIAN | K13: HASIL | L13: KETERANGAN
G14: HR | H14: USER-1 | I14: USER-2 | J14: MANAGER
C16: GRAND TOTAL PENILAIAN | E16: =E17+E21+E27+E43+E60+E65+E69 -> 1 | G16: =G17+G21+G27+G43+G60+G65+G69 -> 48.7 | H16: =H17+H21+H27+H43+H60+H65+H69 -> 57.5 | I16: =I17+I21+I27+I43+I60+I65+I69 -> 59 | J16: =J17+J21+J27+J43+J60+J65+J69 -> 60.9 | K16: =K17+K21+K27+K43+K60+K65+K69 -> 57.525
B17: A | C17: PENGALAMAN | E17: =SUM(E18:E19) -> 0.1 | G17: =SUM(G18:G20) -> 0 | H17: =SUM(H18:H20) -> 0 | I17: =SUM(I18:I20) -> 4 | J17: =SUM(J18:J20) -> 4 | K17: =SUM(K18:K20) -> 2
A18: A100 | B18: 1 | C18: =VLOOKUP($A18,PERTANYAAN!$A$18:$E$71,3,0) -> Pengalaman di dalam Daniswara Group | D18: =VLOOKUP($A18,PERTANYAAN!$A$18:$E$71,4,0) -> Apakah ada Pengalaman di Daniswara Group? Bagaimana pandangan anda terkait Daniswara Group? | E18: =VLOOKUP($A18,PERTANYAAN!$A$18:$E$71,5,0) -> 0.06 | G18: ='HR (SADAM)'!M18 -> 0 | H18: ='USER1-SADAM'!M18 -> 0 | I18: ='USER2-SADAM'!M18 -> 0 | J18: ='MANAGER-SADAM'!M18 -> 0 | K18: =AVERAGE(G18:J18) -> 0
A19: A200 | B19: =B18+1 -> 2 | C19: =VLOOKUP($A19,PERTANYAAN!$A$18:$E$71,3,0) -> Pengalaman di luar Daniswara Group | D19: =VLOOKUP($A19,PERTANYAAN!$A$18:$E$71,4,0) -> Jika tidak, apakah sudah ada pengalaman sejenis di luar Daniswara? | E19: =VLOOKUP($A19,PERTANYAAN!$A$18:$E$71,5,0) -> 0.04 | G19: ='HR (SADAM)'!M19 -> 0 | H19: ='USER1-SADAM'!M19 -> 0 | I19: ='USER2-SADAM'!M19 -> 4 | J19: ='MANAGER-SADAM'!M19 -> 4 | K19: =AVERAGE(G19:J19) -> 2
B21: B | C21: ADMINISTRASI | E21: =SUM(E22:E25) -> 0.05 | G21: =SUM(G22:G25) -> 5 | H21: =SUM(H22:H25) -> 5 | I21: =SUM(I22:I25) -> 5 | J21: =SUM(J22:J25) -> 5 | K21: =SUM(K22:K25) -> 5
A22: B100 | B22: 1 | C22: =VLOOKUP($A22,PERTANYAAN!$A$18:$E$71,3,0) -> Identitas (KTP & KK) | D22: =VLOOKUP($A22,PERTANYAAN!$A$18:$E$71,4,0) -> Apakah ada Identitas Diri KTP & KK? | E22: =VLOOKUP($A22,PERTANYAAN!$A$18:$E$71,5,0) -> 0.01 | G22: ='HR (SADAM)'!M22 -> 1 | H22: ='USER1-SADAM'!M22 -> 1 | I22: ='USER2-SADAM'!M22 -> 1 | J22: ='MANAGER-SADAM'!M22 -> 1 | K22: =AVERAGE(G22:J22) -> 1
A23: B200 | B23: =B22+1 -> 2 | C23: =VLOOKUP($A23,PERTANYAAN!$A$18:$E$71,3,0) -> SIM A (utk jabatan di Divisi Operasi) | D23: =VLOOKUP($A23,PERTANYAAN!$A$18:$E$71,4,0) -> Apakah sudah memiliki SIM A? | E23: =VLOOKUP($A23,PERTANYAAN!$A$18:$E$71,5,0) -> 0.02 | G23: ='HR (SADAM)'!M23 -> 2 | H23: ='USER1-SADAM'!M23 -> 2 | I23: ='USER2-SADAM'!M23 -> 2 | J23: ='MANAGER-SADAM'!M23 -> 2 | K23: =AVERAGE(G23:J23) -> 2
A24: B300 | B24: =B23+1 -> 3 | C24: =VLOOKUP($A24,PERTANYAAN!$A$18:$E$71,3,0) -> SIM C | D24: =VLOOKUP($A24,PERTANYAAN!$A$18:$E$71,4,0) -> Apakah sudah memiliki SIM C? | E24: =VLOOKUP($A24,PERTANYAAN!$A$18:$E$71,5,0) -> 0.01 | G24: ='HR (SADAM)'!M24 -> 1 | H24: ='USER1-SADAM'!M24 -> 1 | I24: ='USER2-SADAM'!M24 -> 1 | J24: ='MANAGER-SADAM'!M24 -> 1 | K24: =AVERAGE(G24:J24) -> 1
A25: B400 | B25: =B24+1 -> 4 | C25: =VLOOKUP($A25,PERTANYAAN!$A$18:$E$71,3,0) -> NPWP | D25: =VLOOKUP($A25,PERTANYAAN!$A$18:$E$71,4,0) -> Apakah sudah Memiliki NPWP? | E25: =VLOOKUP($A25,PERTANYAAN!$A$18:$E$71,5,0) -> 0.01 | G25: ='HR (SADAM)'!M25 -> 1 | H25: ='USER1-SADAM'!M25 -> 1 | I25: ='USER2-SADAM'!M25 -> 1 | J25: ='MANAGER-SADAM'!M25 -> 1 | K25: =AVERAGE(G25:J25) -> 1
B27: C | C27: HARD SKILL | E27: =E28 -> 0.35 | G27: =G28 -> 14 | H27: =H28 -> 22 | I27: =I28 -> 17 | J27: =J28 -> 19.5 | K27: =K28 -> 18.125
A28: C100 | B28: 1 | C28: =VLOOKUP($A28,PERTANYAAN!$A$18:$E$71,3,0) -> Operasi / Logistik | E28: =VLOOKUP($A28,PERTANYAAN!$A$18:$E$71,5,0) -> 0.35 | G28: =SUM(G29:G33) -> 14 | H28: =SUM(H29:H33) -> 22 | I28: =SUM(I29:I33) -> 17 | J28: =SUM(J29:J33) -> 19.5 | K28: =SUM(K29:K33) -> 18.125
A29: C110 | B29: - | C29: =VLOOKUP($A29,PERTANYAAN!$A$18:$E$71,3,0) -> Skill Mengemudi | D29: =VLOOKUP($A29,PERTANYAAN!$A$18:$E$71,4,0) -> Coba ceritakan pengalaman / keahlian dalam mengemudi mobil angkut/logistik? | E29: =VLOOKUP($A29,PERTANYAAN!$A$18:$E$71,5,0) -> 0.15 | G29: ='HR (SADAM)'!M29 -> 6 | H29: ='USER1-SADAM'!M29 -> 12 | I29: ='USER2-SADAM'!M29 -> 9 | J29: ='MANAGER-SADAM'!M29 -> 9 | K29: =AVERAGE(G29:J29) -> 9
A30: C120 | B30: - | C30: =VLOOKUP($A30,PERTANYAAN!$A$18:$E$71,3,0) -> Flow Administrasi Logistik | D30: =VLOOKUP($A30,PERTANYAAN!$A$18:$E$71,4,0) -> Coba ceritakan yang anda ketahui tentang alur administrasi logistik? Dan kaitannya dengan Ms. Office | E30: =VLOOKUP($A30,PERTANYAAN!$A$18:$E$71,5,0) -> 0.1 | G30: ='HR (SADAM)'!M30 -> 4 | H30: ='USER1-SADAM'!M30 -> 4 | I30: ='USER2-SADAM'!M30 -> 4 | J30: ='MANAGER-SADAM'!M30 -> 6 | K30: =AVERAGE(G30:J30) -> 4.5
A31: C130 | B31: - | C31: =VLOOKUP($A31,PERTANYAAN!$A$18:$E$71,3,0) -> Pengetahuan terkait logistik | D31: =VLOOKUP($A31,PERTANYAAN!$A$18:$E$71,4,0) -> Ceritakan yang anda ketahui terkait dengan logistik? | E31: =VLOOKUP($A31,PERTANYAAN!$A$18:$E$71,5,0) -> 0.025 | G31: ='HR (SADAM)'!M31 -> 1 | H31: ='USER1-SADAM'!M31 -> 1.5 | I31: ='USER2-SADAM'!M31 -> 1 | J31: ='MANAGER-SADAM'!M31 -> 1.5 | K31: =AVERAGE(G31:J31) -> 1.25
A32: C140 | B32: - | C32: =VLOOKUP($A32,PERTANYAAN!$A$18:$E$71,3,0) -> Pengalaman di Bongkar Muat | D32: =VLOOKUP($A32,PERTANYAAN!$A$18:$E$71,4,0) -> Apakah memiliki pengalaman terkait bongkar muat?sedalam apa? | E32: =VLOOKUP($A32,PERTANYAAN!$A$18:$E$71,5,0) -> 0.075 | G32: ='HR (SADAM)'!M32 -> 3 | H32: ='USER1-SADAM'!M32 -> 4.5 | I32: ='USER2-SADAM'!M32 -> 3 | J32: ='MANAGER-SADAM'!M32 -> 3 | K32: =AVERAGE(G32:J32) -> 3.375
B34: =B28+1 -> 2 | C34: Keuangan | E34: =SUM(E35:E37) -> 0.35
B35: - | C35: Skill Akuntansi & Input Data | E35: 0.15
B36: - | C36: Microsoft Office | E36: 0.2
B38: 3 | C38: Busdev & HR
B39: - | C39: Pengalaman Kreatif
B40: - | C40: Organisasi Perusahaan & Lembaga
B41: -
B43: D | C43: SOFT SKILL | E43: =E44 -> 0.25 | G43: =G44 -> 14 | H43: =H44 -> 16.5 | I43: =I44 -> 16.5 | J43: =J44 -> 20.5 | K43: =K44 -> 16.875
A44: D100 | B44: 1 | C44: =VLOOKUP($A44,PERTANYAAN!$A$18:$E$71,3,0) -> Staff | E44: =SUM(E45:E49) -> 0.25 | G44: =SUM(G45:G48) -> 14 | H44: =SUM(H45:H48) -> 16.5 | I44: =SUM(I45:I48) -> 16.5 | J44: =SUM(J45:J48) -> 20.5 | K44: =SUM(K45:K48) -> 16.875
A45: D110 | B45: - | C45: =VLOOKUP($A45,PERTANYAAN!$A$18:$E$71,3,0) -> Kepemimpinan | D45: =VLOOKUP($A45,PERTANYAAN!$A$18:$E$71,4,0) -> Jika terjadi suatu diskusi dalam group/kelompok yang belum menemukan titik temu, apa yang akan anda lakukan? | E45: =VLOOKUP($A45,PERTANYAAN!$A$18:$E$71,5,0) -> 0.025 | G45: ='HR (SADAM)'!M45 -> 1 | H45: ='USER1-SADAM'!M45 -> 1.5 | I45: ='USER2-SADAM'!M45 -> 1.5 | J45: ='MANAGER-SADAM'!M45 -> 1.5 | K45: =AVERAGE(G45:J45) -> 1.375
A46: D120 | B46: - | C46: =VLOOKUP($A46,PERTANYAAN!$A$18:$E$71,3,0) -> Komunikasi | D46: =VLOOKUP($A46,PERTANYAAN!$A$18:$E$71,4,0) -> Bagaimana hubungan kerjasama antar sesama pegawai / organisasi / kelompok?(jika memiliki pengalaman kerja) | E46: =VLOOKUP($A46,PERTANYAAN!$A$18:$E$71,5,0) -> 0.1 | G46: ='HR (SADAM)'!M46 -> 6 | H46: ='USER1-SADAM'!M46 -> 6 | I46: ='USER2-SADAM'!M46 -> 8 | J46: ='MANAGER-SADAM'!M46 -> 8 | K46: =AVERAGE(G46:J46) -> 7
A47: D130 | B47: - | C47: =VLOOKUP($A47,PERTANYAAN!$A$18:$E$71,3,0) -> Patuh pada Peraturan / Commitment | D47: =VLOOKUP($A47,PERTANYAAN!$A$18:$E$71,4,0) -> Bagaimana pandangan anda terkait perusahaan dan aturan yang dapat berubah ubah sesuai arah perusahaan? | E47: =VLOOKUP($A47,PERTANYAAN!$A$18:$E$71,5,0) -> 0.05 | G47: ='HR (SADAM)'!M47 -> 4 | H47: ='USER1-SADAM'!M47 -> 3 | I47: ='USER2-SADAM'!M47 -> 4 | J47: ='MANAGER-SADAM'!M47 -> 5 | K47: =AVERAGE(G47:J47) -> 4
A48: D140 | B48: - | C48: =VLOOKUP($A48,PERTANYAAN!$A$18:$E$71,3,0) -> Determinasi thd tekanan | D48: =VLOOKUP($A48,PERTANYAAN!$A$18:$E$71,4,0) -> Bagaimana pandangan anda jika anda dituntut pada pekerjaan diluar dari waktu normal dalam bekerja? | E48: =VLOOKUP($A48,PERTANYAAN!$A$18:$E$71,5,0) -> 0.075 | G48: ='HR (SADAM)'!M48 -> 3 | H48: ='USER1-SADAM'!M48 -> 6 | I48: ='USER2-SADAM'!M48 -> 3 | J48: ='MANAGER-SADAM'!M48 -> 6 | K48: =AVERAGE(G48:J48) -> 4.5
B50: 2 | C50: Supervisor
...

Sheet HASIL-IMAN
A1: FORM PENILAIAN PEGAWAI & CALON PEGAWAI
A2: DANISWARA GROUP
A5: NAMA | B5: : | C5: IMAN
A6: POSISI PELAMAR | B6: : | C6: STAFF OPERASI
A7: PENEMPATAN | B7: : | C7: IKN - KALIMANTAN TIMUR
A8: DIVISI | B8: : | C8: OPERASI
A9: BUDGET SALARY | B9: : | C9: RANGE 4 JT - 4,8 JT (ALL IN - IKN)
A10: HR | B10: : | C10: ANGGY PERMANA PUTRA
A11: HASIL PENILAIAN | B11: : | C11: =K16 -> 77.933333
A13: KODE ACC | B13: NO. | C13: KATEGORI | D13: PERTANYAAN | E13: BOBOT | G13: PENILAIAN | K13: HASIL | L13: KETERANGAN
G14: HR | H14: USER-1 | I14: USER-2 | J14: MANAGER
C16: GRAND TOTAL PENILAIAN | E16: =E17+E21+E27+E43+E60+E65+E69 -> 1 | G16: =G17+G21+G27+G43+G60+G65+G69 -> 79.7 | H16: =H17+H21+H27+H43+H60+H65+H69 -> 81.9 | I16: =I17+I21+I27+I43+I60+I65+I69 -> 78.6 | J16: =J17+J21+J27+J43+J60+J65+J69 -> 67.2 | K16: =K17+K21+K27+K43+K60+K65+K69 -> 77.933333
B17: A | C17: PENGALAMAN | E17: =SUM(E18:E19) -> 0.1 | G17: =SUM(G18:G20) -> 4 | H17: =SUM(H18:H20) -> 4 | I17: =SUM(I18:I20) -> 4 | J17: =SUM(J18:J20) -> 4 | K17: =SUM(K18:K20) -> 4
A18: A100 | B18: 1 | C18: =VLOOKUP($A18,PERTANYAAN!$A$18:$E$71,3,0) -> Pengalaman di dalam Daniswara Group | D18: =VLOOKUP($A18,PERTANYAAN!$A$18:$E$71,4,0) -> Apakah ada Pengalaman di Daniswara Group? Bagaimana pandangan anda terkait Daniswara Group? | E18: =VLOOKUP($A18,PERTANYAAN!$A$18:$E$71,5,0) -> 0.06 | G18: ='HR (IMAN)'!M18 -> 0 | H18: ='USER1-IMAN'!M18 -> 0 | I18: ='USER2-IMAN'!M18 -> 0 | J18: ='MANAGER-IMAN'!M18 -> 0 | K18: =AVERAGE(G18:J18) -> 0
A19: A200 | B19: =B18+1 -> 2 | C19: =VLOOKUP($A19,PERTANYAAN!$A$18:$E$71,3,0) -> Pengalaman di luar Daniswara Group | D19: =VLOOKUP($A19,PERTANYAAN!$A$18:$E$71,4,0) -> Jika tidak, apakah sudah ada pengalaman sejenis di luar Daniswara? | E19: =VLOOKUP($A19,PERTANYAAN!$A$18:$E$71,5,0) -> 0.04 | G19: ='HR (IMAN)'!M19 -> 4 | H19: ='USER1-IMAN'!M19 -> 4 | I19: ='USER2-IMAN'!M19 -> 4 | J19: ='MANAGER-IMAN'!M19 -> 4 | K19: =AVERAGE(G19:J19) -> 4
B21: B | C21: ADMINISTRASI | E21: =SUM(E22:E25) -> 0.05 | G21: =SUM(G22:G25) -> 4 | H21: =SUM(H22:H25) -> 4 | I21: =SUM(I22:I25) -> 4 | J21: =SUM(J22:J25) -> 4 | K21: =SUM(K22:K25) -> 4
A22: B100 | B22: 1 | C22: =VLOOKUP($A22,PERTANYAAN!$A$18:$E$71,3,0) -> Identitas (KTP & KK) | D22: =VLOOKUP($A22,PERTANYAAN!$A$18:$E$71,4,0) -> Apakah ada Identitas Diri KTP & KK? | E22: =VLOOKUP($A22,PERTANYAAN!$A$18:$E$71,5,0) -> 0.01 | G22: ='HR (IMAN)'!M22 -> 1 | H22: ='USER1-IMAN'!M22 -> 1 | I22: ='USER2-IMAN'!M22 -> 1 | J22: ='MANAGER-IMAN'!M22 -> 1 | K22: =AVERAGE(G22:J22) -> 1
A23: B200 | B23: =B22+1 -> 2 | C23: =VLOOKUP($A23,PERTANYAAN!$A$18:$E$71,3,0) -> SIM A (utk jabatan di Divisi Operasi) | D23: =VLOOKUP($A23,PERTANYAAN!$A$18:$E$71,4,0) -> Apakah sudah memiliki SIM A? | E23: =VLOOKUP($A23,PERTANYAAN!$A$18:$E$71,5,0) -> 0.02 | G23: ='HR (IMAN)'!M23 -> 2 | H23: ='USER1-IMAN'!M23 -> 2 | I23: ='USER2-IMAN'!M23 -> 2 | J23: ='MANAGER-IMAN'!M23 -> 2 | K23: =AVERAGE(G23:J23) -> 2
A24: B300 | B24: =B23+1 -> 3 | C24: =VLOOKUP($A24,PERTANYAAN!$A$18:$E$71,3,0) -> SIM C | D24: =VLOOKUP($A24,PERTANYAAN!$A$18:$E$71,4,0) -> Apakah sudah memiliki SIM C? | E24: =VLOOKUP($A24,PERTANYAAN!$A$18:$E$71,5,0) -> 0.01 | G24: ='HR (IMAN)'!M24 -> 0 | H24: ='USER1-IMAN'!M24 -> 0 | I24: ='USER2-IMAN'!M24 -> 0 | J24: ='MANAGER-IMAN'!M24 -> 0 | K24: =AVERAGE(G24:J24) -> 0
A25: B400 | B25: =B24+1 -> 4 | C25: =VLOOKUP($A25,PERTANYAAN!$A$18:$E$71,3,0) -> NPWP | D25: =VLOOKUP($A25,PERTANYAAN!$A$18:$E$71,4,0) -> Apakah sudah Memiliki NPWP? | E25: =VLOOKUP($A25,PERTANYAAN!$A$18:$E$71,5,0) -> 0.01 | G25: ='HR (IMAN)'!M25 -> 1 | H25: ='USER1-IMAN'!M25 -> 1 | I25: ='USER2-IMAN'!M25 -> 1 | J25: ='MANAGER-IMAN'!M25 -> 1 | K25: =AVERAGE(G25:J25) -> 1
B27: C | C27: HARD SKILL | E27: =E28 -> 0.35 | G27: =G28 -> 30.5 | H27: =H28 -> 33 | I27: =I28 -> 32.5 | J27: =J28 -> 33 | K27: =K28 -> 32.25
A28: C100 | B28: 1 | C28: =VLOOKUP($A28,PERTANYAAN!$A$18:$E$71,3,0) -> Operasi / Logistik | E28: =VLOOKUP($A28,PERTANYAAN!$A$18:$E$71,5,0) -> 0.35 | G28: =SUM(G29:G33) -> 30.5 | H28: =SUM(H29:H33) -> 33 | I28: =SUM(I29:I33) -> 32.5 | J28: =SUM(J29:J33) -> 33 | K28: =SUM(K29:K33) -> 32.25
A29: C110 | B29: - | C29: =VLOOKUP($A29,PERTANYAAN!$A$18:$E$71,3,0) -> Skill Mengemudi | D29: =VLOOKUP($A29,PERTANYAAN!$A$18:$E$71,4,0) -> Coba ceritakan pengalaman / keahlian dalam mengemudi mobil angkut/logistik? | E29: =VLOOKUP($A29,PERTANYAAN!$A$18:$E$71,5,0) -> 0.15 | G29: ='HR (IMAN)'!M29 -> 15 | H29: ='USER1-IMAN'!M29 -> 15 | I29: ='USER2-IMAN'!M29 -> 15 | J29: ='MANAGER-IMAN'!M29 -> 15 | K29: =AVERAGE(G29:J29) -> 15
A30: C120 | B30: - | C30: =VLOOKUP($A30,PERTANYAAN!$A$18:$E$71,3,0) -> Flow Administrasi Logistik | D30: =VLOOKUP($A30,PERTANYAAN!$A$18:$E$71,4,0) -> Coba ceritakan yang anda ketahui tentang alur administrasi logistik? Dan kaitannya dengan Ms. Office | E30: =VLOOKUP($A30,PERTANYAAN!$A$18:$E$71,5,0) -> 0.1 | G30: ='HR (IMAN)'!M30 -> 6 | H30: ='USER1-IMAN'!M30 -> 8 | I30: ='USER2-IMAN'!M30 -> 8 | J30: ='MANAGER-IMAN'!M30 -> 8 | K30: =AVERAGE(G30:J30) -> 7.5
A31: C130 | B31: - | C31: =VLOOKUP($A31,PERTANYAAN!$A$18:$E$71,3,0) -> Pengetahuan terkait logistik | D31: =VLOOKUP($A31,PERTANYAAN!$A$18:$E$71,4,0) -> Ceritakan yang anda ketahui terkait dengan logistik? | E31: =VLOOKUP($A31,PERTANYAAN!$A$18:$E$71,5,0) -> 0.025 | G31: ='HR (IMAN)'!M31 -> 2 | H31: ='USER1-IMAN'!M31 -> 2.5 | I31: ='USER2-IMAN'!M31 -> 2 | J31: ='MANAGER-IMAN'!M31 -> 2.5 | K31: =AVERAGE(G31:J31) -> 2.25
A32: C140 | B32: - | C32: =VLOOKUP($A32,PERTANYAAN!$A$18:$E$71,3,0) -> Pengalaman di Bongkar Muat | D32: =VLOOKUP($A32,PERTANYAAN!$A$18:$E$71,4,0) -> Apakah memiliki pengalaman terkait bongkar muat?sedalam apa? | E32: =VLOOKUP($A32,PERTANYAAN!$A$18:$E$71,5,0) -> 0.075 | G32: ='HR (IMAN)'!M32 -> 7.5 | H32: ='USER1-IMAN'!M32 -> 7.5 | I32: ='USER2-IMAN'!M32 -> 7.5 | J32: ='MANAGER-IMAN'!M32 -> 7.5 | K32: =AVERAGE(G32:J32) -> 7.5
B34: =B28+1 -> 2 | C34: Keuangan | E34: =SUM(E35:E37) -> 0.35
B35: - | C35: Skill Akuntansi & Input Data | E35: 0.15
B36: - | C36: Microsoft Office | E36: 0.2
B38: 3 | C38: Busdev & HR
B39: - | C39: Pengalaman Kreatif
B40: - | C40: Organisasi Perusahaan & Lembaga
B41: -
B43: D | C43: SOFT SKILL | E43: =E44 -> 0.25 | G43: =G44 -> 20.5 | H43: =H44 -> 20.5 | I43: =I44 -> 19 | J43: =J44 -> 15.5 | K43: =K44 -> 18.875
A44: D100 | B44: 1 | C44: =VLOOKUP($A44,PERTANYAAN!$A$18:$E$71,3,0) -> Staff | E44: =SUM(E45:E49) -> 0.25 | G44: =SUM(G45:G48) -> 20.5 | H44: =SUM(H45:H48) -> 20.5 | I44: =SUM(I45:I48) -> 19 | J44: =SUM(J45:J48) -> 15.5 | K44: =SUM(K45:K48) -> 18.875
A45: D110 | B45: - | C45: =VLOOKUP($A45,PERTANYAAN!$A$18:$E$71,3,0) -> Kepemimpinan | D45: =VLOOKUP($A45,PERTANYAAN!$A$18:$E$71,4,0) -> Jika terjadi suatu diskusi dalam group/kelompok yang belum menemukan titik temu, apa yang akan anda lakukan? | E45: =VLOOKUP($A45,PERTANYAAN!$A$18:$E$71,5,0) -> 0.025 | G45: ='HR (IMAN)'!M45 -> 1 | H45: ='USER1-IMAN'!M45 -> 1 | I45: ='USER2-IMAN'!M45 -> 1 | J45: ='MANAGER-IMAN'!M45 -> 0.5 | K45: =AVERAGE(G45:J45) -> 0.875
A46: D120 | B46: - | C46: =VLOOKUP($A46,PERTANYAAN!$A$18:$E$71,3,0) -> Komunikasi | D46: =VLOOKUP($A46,PERTANYAAN!$A$18:$E$71,4,0) -> Bagaimana hubungan kerjasama antar sesama pegawai / organisasi / kelompok?(jika memiliki pengalaman kerja) | E46: =VLOOKUP($A46,PERTANYAAN!$A$18:$E$71,5,0) -> 0.1 | G46: ='HR (IMAN)'!M46 -> 8 | H46: ='USER1-IMAN'!M46 -> 8 | I46: ='USER2-IMAN'!M46 -> 8 | J46: ='MANAGER-IMAN'!M46 -> 6 | K46: =AVERAGE(G46:J46) -> 7.5
A47: D130 | B47: - | C47: =VLOOKUP($A47,PERTANYAAN!$A$18:$E$71,3,0) -> Patuh pada Peraturan / Commitment | D47: =VLOOKUP($A47,PERTANYAAN!$A$18:$E$71,4,0) -> Bagaimana pandangan anda terkait perusahaan dan aturan yang dapat berubah ubah sesuai arah perusahaan? | E47: =VLOOKUP($A47,PERTANYAAN!$A$18:$E$71,5,0) -> 0.05 | G47: ='HR (IMAN)'!M47 -> 4 | H47: ='USER1-IMAN'!M47 -> 4 | I47: ='USER2-IMAN'!M47 -> 4 | J47: ='MANAGER-IMAN'!M47 -> 3 | K47: =AVERAGE(G47:J47) -> 3.75
A48: D140 | B48: - | C48: =VLOOKUP($A48,PERTANYAAN!$A$18:$E$71,3,0) -> Determinasi thd tekanan | D48: =VLOOKUP($A48,PERTANYAAN!$A$18:$E$71,4,0) -> Bagaimana pandangan anda jika anda dituntut pada pekerjaan diluar dari waktu normal dalam bekerja? | E48: =VLOOKUP($A48,PERTANYAAN!$A$18:$E$71,5,0) -> 0.075 | G48: ='HR (IMAN)'!M48 -> 7.5 | H48: ='USER1-IMAN'!M48 -> 7.5 | I48: ='USER2-IMAN'!M48 -> 6 | J48: ='MANAGER-IMAN'!M48 -> 6 | K48: =AVERAGE(G48:J48) -> 6.75
B50: 2 | C50: Supervisor
...

Sheet HASIL-DENY
A1: FORM PENILAIAN PEGAWAI & CALON PEGAWAI
A2: DANISWARA GROUP
A5: NAMA | B5: : | C5: DENY
A6: POSISI PELAMAR | B6: : | C6: STAFF OPERASI
A7: PENEMPATAN | B7: : | C7: IKN - KALIMANTAN TIMUR
A8: DIVISI | B8: : | C8: OPERASI
A9: BUDGET SALARY | B9: : | C9: RANGE 4 JT - 4,8 JT (ALL IN - IKN)
A10: HR | B10: : | C10: ANGGY PERMANA PUTRA
A11: HASIL PENILAIAN | B11: : | C11: =K16 -> 84.75
A13: KODE ACC | B13: NO. | C13: KATEGORI | D13: PERTANYAAN | E13: BOBOT | G13: PENILAIAN | K13: HASIL | L13: KETERANGAN
G14: HR | H14: USER-1 | I14: USER-2 | J14: MANAGER
C16: GRAND TOTAL PENILAIAN | E16: =E17+E21+E27+E43+E60+E65+E69 -> 1 | G16: =G17+G21+G27+G43+G60+G65+G69 -> 88 | H16: =H17+H21+H27+H43+H60+H65+H69 -> 86 | I16: =I17+I21+I27+I43+I60+I65+I69 -> 83 | J16: =J17+J21+J27+J43+J60+J65+J69 -> 77 | K16: =K17+K21+K27+K43+K60+K65+K69 -> 84.75
B17: A | C17: PENGALAMAN | E17: =SUM(E18:E19) -> 0.1 | G17: =SUM(G18:G20) -> 6 | H17: =SUM(H18:H20) -> 6 | I17: =SUM(I18:I20) -> 6 | J17: =SUM(J18:J20) -> 10 | K17: =SUM(K18:K20) -> 7
A18: A100 | B18: 1 | C18: =VLOOKUP($A18,PERTANYAAN!$A$18:$E$71,3,0) -> Pengalaman di dalam Daniswara Group | D18: =VLOOKUP($A18,PERTANYAAN!$A$18:$E$71,4,0) -> Apakah ada Pengalaman di Daniswara Group? Bagaimana pandangan anda terkait Daniswara Group? | E18: =VLOOKUP($A18,PERTANYAAN!$A$18:$E$71,5,0) -> 0.06 | G18: ='HR (DENY)'!M18 -> 6 | H18: ='USER1-DENY'!M18 -> 6 | I18: ='USER2-DENY'!M18 -> 6 | J18: ='MANAGER-DENY'!M18 -> 6 | K18: =AVERAGE(G18:J18) -> 6
A19: A200 | B19: =B18+1 -> 2 | C19: =VLOOKUP($A19,PERTANYAAN!$A$18:$E$71,3,0) -> Pengalaman di luar Daniswara Group | D19: =VLOOKUP($A19,PERTANYAAN!$A$18:$E$71,4,0) -> Jika tidak, apakah sudah ada pengalaman sejenis di luar Daniswara? | E19: =VLOOKUP($A19,PERTANYAAN!$A$18:$E$71,5,0) -> 0.04 | G19: ='HR (DENY)'!M19 -> 0 | H19: ='USER1-DENY'!M19 -> 0 | I19: ='USER2-DENY'!M19 -> 0 | J19: ='MANAGER-DENY'!M19 -> 4 | K19: =AVERAGE(G19:J19) -> 1
B21: B | C21: ADMINISTRASI | E21: =SUM(E22:E25) -> 0.05 | G21: =SUM(G22:G25) -> 5 | H21: =SUM(H22:H25) -> 5 | I21: =SUM(I22:I25) -> 3 | J21: =SUM(J22:J25) -> 3 | K21: =SUM(K22:K25) -> 4
A22: B100 | B22: 1 | C22: =VLOOKUP($A22,PERTANYAAN!$A$18:$E$71,3,0) -> Identitas (KTP & KK) | D22: =VLOOKUP($A22,PERTANYAAN!$A$18:$E$71,4,0) -> Apakah ada Identitas Diri KTP & KK? | E22: =VLOOKUP($A22,PERTANYAAN!$A$18:$E$71,5,0) -> 0.01 | G22: ='HR (DENY)'!M22 -> 1 | H22: ='USER1-DENY'!M22 -> 1 | I22: ='USER2-DENY'!M22 -> 1 | J22: ='MANAGER-DENY'!M22 -> 1 | K22: =AVERAGE(G22:J22) -> 1
A23: B200 | B23: =B22+1 -> 2 | C23: =VLOOKUP($A23,PERTANYAAN!$A$18:$E$71,3,0) -> SIM A (utk jabatan di Divisi Operasi) | D23: =VLOOKUP($A23,PERTANYAAN!$A$18:$E$71,4,0) -> Apakah sudah memiliki SIM A? | E23: =VLOOKUP($A23,PERTANYAAN!$A$18:$E$71,5,0) -> 0.02 | G23: ='HR (DENY)'!M23 -> 2 | H23: ='USER1-DENY'!M23 -> 2 | I23: ='USER2-DENY'!M23 -> 0 | J23: ='MANAGER-DENY'!M23 -> 0 | K23: =AVERAGE(G23:J23) -> 1
A24: B300 | B24: =B23+1 -> 3 | C24: =VLOOKUP($A24,PERTANYAAN!$A$18:$E$71,3,0) -> SIM C | D24: =VLOOKUP($A24,PERTANYAAN!$A$18:$E$71,4,0) -> Apakah sudah memiliki SIM C? | E24: =VLOOKUP($A24,PERTANYAAN!$A$18:$E$71,5,0) -> 0.01 | G24: ='HR (DENY)'!M24 -> 1 | H24: ='USER1-DENY'!M24 -> 1 | I24: ='USER2-DENY'!M24 -> 1 | J24: ='MANAGER-DENY'!M24 -> 1 | K24: =AVERAGE(G24:J24) -> 1
A25: B400 | B25: =B24+1 -> 4 | C25: =VLOOKUP($A25,PERTANYAAN!$A$18:$E$71,3,0) -> NPWP | D25: =VLOOKUP($A25,PERTANYAAN!$A$18:$E$71,4,0) -> Apakah sudah Memiliki NPWP? | E25: =VLOOKUP($A25,PERTANYAAN!$A$18:$E$71,5,0) -> 0.01 | G25: ='HR (DENY)'!M25 -> 1 | H25: ='USER1-DENY'!M25 -> 1 | I25: ='USER2-DENY'!M25 -> 1 | J25: ='MANAGER-DENY'!M25 -> 1 | K25: =AVERAGE(G25:J25) -> 1
B27: C | C27: HARD SKILL | E27: =E28 -> 0.35 | G27: =G28 -> 27 | H27: =H28 -> 25 | I27: =I28 -> 28 | J27: =J28 -> 22.5 | K27: =K28 -> 25.625
A28: C100 | B28: 1 | C28: =VLOOKUP($A28,PERTANYAAN!$A$18:$E$71,3,0) -> Operasi / Logistik | E28: =VLOOKUP($A28,PERTANYAAN!$A$18:$E$71,5,0) -> 0.35 | G28: =SUM(G29:G33) -> 27 | H28: =SUM(H29:H33) -> 25 | I28: =SUM(I29:I33) -> 28 | J28: =SUM(J29:J33) -> 22.5 | K28: =SUM(K29:K33) -> 25.625
A29: C110 | B29: - | C29: =VLOOKUP($A29,PERTANYAAN!$A$18:$E$71,3,0) -> Skill Mengemudi | D29: =VLOOKUP($A29,PERTANYAAN!$A$18:$E$71,4,0) -> Coba ceritakan pengalaman / keahlian dalam mengemudi mobil angkut/logistik? | E29: =VLOOKUP($A29,PERTANYAAN!$A$18:$E$71,5,0) -> 0.15 | G29: ='HR (DENY)'!M29 -> 9 | H29: ='USER1-DENY'!M29 -> 9 | I29: ='USER2-DENY'!M29 -> 12 | J29: ='MANAGER-DENY'!M29 -> 6 | K29: =AVERAGE(G29:J29) -> 9
A30: C120 | B30: - | C30: =VLOOKUP($A30,PERTANYAAN!$A$18:$E$71,3,0) -> Flow Administrasi Logistik | D30: =VLOOKUP($A30,PERTANYAAN!$A$18:$E$71,4,0) -> Coba ceritakan yang anda ketahui tentang alur administrasi logistik? Dan kaitannya dengan Ms. Office | E30: =VLOOKUP($A30,PERTANYAAN!$A$18:$E$71,5,0) -> 0.1 | G30: ='HR (DENY)'!M30 -> 8 | H30: ='USER1-DENY'!M30 -> 8 | I30: ='USER2-DENY'!M30 -> 8 | J30: ='MANAGER-DENY'!M30 -> 8 | K30: =AVERAGE(G30:J30) -> 8
A31: C130 | B31: - | C31: =VLOOKUP($A31,PERTANYAAN!$A$18:$E$71,3,0) -> Pengetahuan terkait logistik | D31: =VLOOKUP($A31,PERTANYAAN!$A$18:$E$71,4,0) -> Ceritakan yang anda ketahui terkait dengan logistik? | E31: =VLOOKUP($A31,PERTANYAAN!$A$18:$E$71,5,0) -> 0.025 | G31: ='HR (DENY)'!M31 -> 2.5 | H31: ='USER1-DENY'!M31 -> 2 | I31: ='USER2-DENY'!M31 -> 2 | J31: ='MANAGER-DENY'!M31 -> 2.5 | K31: =AVERAGE(G31:J31) -> 2.25
A32: C140 | B32: - | C32: =VLOOKUP($A32,PERTANYAAN!$A$18:$E$71,3,0) -> Pengalaman di Bongkar Muat | D32: =VLOOKUP($A32,PERTANYAAN!$A$18:$E$71,4,0) -> Apakah memiliki pengalaman terkait bongkar muat?sedalam apa? | E32: =VLOOKUP($A32,PERTANYAAN!$A$18:$E$71,5,0) -> 0.075 | G32: ='HR (DENY)'!M32 -> 7.5 | H32: ='USER1-DENY'!M32 -> 6 | I32: ='USER2-DENY'!M32 -> 6 | J32: ='MANAGER-DENY'!M32 -> 6 | K32: =AVERAGE(G32:J32) -> 6.375
B34: =B28+1 -> 2 | C34: Keuangan | E34: =SUM(E35:E37) -> 0.35
B35: - | C35: Skill Akuntansi & Input Data | E35: 0.15
B36: - | C36: Microsoft Office | E36: 0.2
B38: 3 | C38: Busdev & HR
B39: - | C39: Pengalaman Kreatif
B40: - | C40: Organisasi Perusahaan & Lembaga
B41: -
B43: D | C43: SOFT SKILL | E43: =E44 -> 0.25 | G43: =G44 -> 25 | H43: =H44 -> 25 | I43: =I44 -> 23.5 | J43: =J44 -> 24 | K43: =K44 -> 24.375
A44: D100 | B44: 1 | C44: =VLOOKUP($A44,PERTANYAAN!$A$18:$E$71,3,0) -> Staff | E44: =SUM(E45:E49) -> 0.25 | G44: =SUM(G45:G48) -> 25 | H44: =SUM(H45:H48) -> 25 | I44: =SUM(I45:I48) -> 23.5 | J44: =SUM(J45:J48) -> 24 | K44: =SUM(K45:K48) -> 24.375
A45: D110 | B45: - | C45: =VLOOKUP($A45,PERTANYAAN!$A$18:$E$71,3,0) -> Kepemimpinan | D45: =VLOOKUP($A45,PERTANYAAN!$A$18:$E$71,4,0) -> Jika terjadi suatu diskusi dalam group/kelompok yang belum menemukan titik temu, apa yang akan anda lakukan? | E45: =VLOOKUP($A45,PERTANYAAN!$A$18:$E$71,5,0) -> 0.025 | G45: ='HR (DENY)'!M45 -> 2.5 | H45: ='USER1-DENY'!M45 -> 2.5 | I45: ='USER2-DENY'!M45 -> 2.5 | J45: ='MANAGER-DENY'!M45 -> 2.5 | K45: =AVERAGE(G45:J45) -> 2.5
A46: D120 | B46: - | C46: =VLOOKUP($A46,PERTANYAAN!$A$18:$E$71,3,0) -> Komunikasi | D46: =VLOOKUP($A46,PERTANYAAN!$A$18:$E$71,4,0) -> Bagaimana hubungan kerjasama antar sesama pegawai / organisasi / kelompok?(jika memiliki pengalaman kerja) | E46: =VLOOKUP($A46,PERTANYAAN!$A$18:$E$71,5,0) -> 0.1 | G46: ='HR (DENY)'!M46 -> 10 | H46: ='USER1-DENY'!M46 -> 10 | I46: ='USER2-DENY'!M46 -> 10 | J46: ='MANAGER-DENY'!M46 -> 10 | K46: =AVERAGE(G46:J46) -> 10
A47: D130 | B47: - | C47: =VLOOKUP($A47,PERTANYAAN!$A$18:$E$71,3,0) -> Patuh pada Peraturan / Commitment | D47: =VLOOKUP($A47,PERTANYAAN!$A$18:$E$71,4,0) -> Bagaimana pandangan anda terkait perusahaan dan aturan yang dapat berubah ubah sesuai arah perusahaan? | E47: =VLOOKUP($A47,PERTANYAAN!$A$18:$E$71,5,0) -> 0.05 | G47: ='HR (DENY)'!M47 -> 5 | H47: ='USER1-DENY'!M47 -> 5 | I47: ='USER2-DENY'!M47 -> 5 | J47: ='MANAGER-DENY'!M47 -> 4 | K47: =AVERAGE(G47:J47) -> 4.75
A48: D140 | B48: - | C48: =VLOOKUP($A48,PERTANYAAN!$A$18:$E$71,3,0) -> Determinasi thd tekanan | D48: =VLOOKUP($A48,PERTANYAAN!$A$18:$E$71,4,0) -> Bagaimana pandangan anda jika anda dituntut pada pekerjaan diluar dari waktu normal dalam bekerja? | E48: =VLOOKUP($A48,PERTANYAAN!$A$18:$E$71,5,0) -> 0.075 | G48: ='HR (DENY)'!M48 -> 7.5 | H48: ='USER1-DENY'!M48 -> 7.5 | I48: ='USER2-DENY'!M48 -> 6 | J48: ='MANAGER-DENY'!M48 -> 7.5 | K48: =AVERAGE(G48:J48) -> 7.125
B50: 2 | C50: Supervisor
...

Sheet HASIL-OPIK
A1: FORM PENILAIAN PEGAWAI & CALON PEGAWAI
A2: DANISWARA GROUP
A5: NAMA | B5: : | C5: TAUFIK
A6: POSISI PELAMAR | B6: : | C6: STAFF OPERASI
A7: PENEMPATAN | B7: : | C7: IKN - KALIMANTAN TIMUR
A8: DIVISI | B8: : | C8: OPERASI
A9: BUDGET SALARY | B9: : | C9: RANGE 4 JT - 4,8 JT (ALL IN - IKN)
A10: HR | B10: : | C10: ANGGY PERMANA PUTRA
A11: HASIL PENILAIAN | B11: : | C11: =K16 -> 77.616667
A13: KODE ACC | B13: NO. | C13: KATEGORI | D13: PERTANYAAN | E13: BOBOT | G13: PENILAIAN | K13: HASIL | L13: KETERANGAN
G14: HR | H14: USER-1 | I14: USER-2 | J14: MANAGER
C16: GRAND TOTAL PENILAIAN | E16: =E17+E21+E27+E43+E60+E65+E69 -> 1 | G16: =G17+G21+G27+G43+G60+G65+G69 -> 91 | H16: =H17+H21+H27+H43+H60+H65+H69 -> 70 | I16: =I17+I21+I27+I43+I60+I65+I69 -> 81.5 | J16: =J17+J21+J27+J43+J60+J65+J69 -> 64.3 | K16: =K17+K21+K27+K43+K60+K65+K69 -> 77.616667
B17: A | C17: PENGALAMAN | E17: =SUM(E18:E19) -> 0.1 | G17: =SUM(G18:G20) -> 6 | H17: =SUM(H18:H20) -> 6 | I17: =SUM(I18:I20) -> 6 | J17: =SUM(J18:J20) -> 6 | K17: =SUM(K18:K20) -> 6
A18: A100 | B18: 1 | C18: =VLOOKUP($A18,PERTANYAAN!$A$18:$E$71,3,0) -> Pengalaman di dalam Daniswara Group | D18: =VLOOKUP($A18,PERTANYAAN!$A$18:$E$71,4,0) -> Apakah ada Pengalaman di Daniswara Group? Bagaimana pandangan anda terkait Daniswara Group? | E18: =VLOOKUP($A18,PERTANYAAN!$A$18:$E$71,5,0) -> 0.06 | G18: ='HR (OPIK)'!M18 -> 6 | H18: ='USER1-TAUFIK'!M18 -> 6 | I18: ='USER2-TAUFIK'!M18 -> 6 | J18: ='MANAGER-TAUFIK'!M18 -> 6 | K18: =AVERAGE(G18:J18) -> 6
A19: A200 | B19: =B18+1 -> 2 | C19: =VLOOKUP($A19,PERTANYAAN!$A$18:$E$71,3,0) -> Pengalaman di luar Daniswara Group | D19: =VLOOKUP($A19,PERTANYAAN!$A$18:$E$71,4,0) -> Jika tidak, apakah sudah ada pengalaman sejenis di luar Daniswara? | E19: =VLOOKUP($A19,PERTANYAAN!$A$18:$E$71,5,0) -> 0.04 | G19: ='HR (OPIK)'!M19 -> 0 | H19: ='USER1-TAUFIK'!M19 -> 0 | I19: ='USER2-TAUFIK'!M19 -> 0 | J19: ='MANAGER-TAUFIK'!M19 -> 0 | K19: =AVERAGE(G19:J19) -> 0
B21: B | C21: ADMINISTRASI | E21: =SUM(E22:E25) -> 0.05 | G21: =SUM(G22:G25) -> 5 | H21: =SUM(H22:H25) -> 5 | I21: =SUM(I22:I25) -> 3 | J21: =SUM(J22:J25) -> 3 | K21: =SUM(K22:K25) -> 4
A22: B100 | B22: 1 | C22: =VLOOKUP($A22,PERTANYAAN!$A$18:$E$71,3,0) -> Identitas (KTP & KK) | D22: =VLOOKUP($A22,PERTANYAAN!$A$18:$E$71,4,0) -> Apakah ada Identitas Diri KTP & KK? | E22: =VLOOKUP($A22,PERTANYAAN!$A$18:$E$71,5,0) -> 0.01 | G22: ='HR (OPIK)'!M22 -> 1 | H22: ='USER1-TAUFIK'!M22 -> 1 | I22: ='USER2-TAUFIK'!M22 -> 1 | J22: ='MANAGER-TAUFIK'!M22 -> 1 | K22: =AVERAGE(G22:J22) -> 1
A23: B200 | B23: =B22+1 -> 2 | C23: =VLOOKUP($A23,PERTANYAAN!$A$18:$E$71,3,0) -> SIM A (utk jabatan di Divisi Operasi) | D23: =VLOOKUP($A23,PERTANYAAN!$A$18:$E$71,4,0) -> Apakah sudah memiliki SIM A? | E23: =VLOOKUP($A23,PERTANYAAN!$A$18:$E$71,5,0) -> 0.02 | G23: ='HR (OPIK)'!M23 -> 2 | H23: ='USER1-TAUFIK'!M23 -> 2 | I23: ='USER2-TAUFIK'!M23 -> 0 | J23: ='MANAGER-TAUFIK'!M23 -> 0 | K23: =AVERAGE(G23:J23) -> 1
A24: B300 | B24: =B23+1 -> 3 | C24: =VLOOKUP($A24,PERTANYAAN!$A$18:$E$71,3,0) -> SIM C | D24: =VLOOKUP($A24,PERTANYAAN!$A$18:$E$71,4,0) -> Apakah sudah memiliki SIM C? | E24: =VLOOKUP($A24,PERTANYAAN!$A$18:$E$71,5,0) -> 0.01 | G24: ='HR (OPIK)'!M24 -> 1 | H24: ='USER1-TAUFIK'!M24 -> 1 | I24: ='USER2-TAUFIK'!M24 -> 1 | J24: ='MANAGER-TAUFIK'!M24 -> 1 | K24: =AVERAGE(G24:J24) -> 1
A25: B400 | B25: =B24+1 -> 4 | C25: =VLOOKUP($A25,PERTANYAAN!$A$18:$E$71,3,0) -> NPWP | D25: =VLOOKUP($A25,PERTANYAAN!$A$18:$E$71,4,0) -> Apakah sudah Memiliki NPWP? | E25: =VLOOKUP($A25,PERTANYAAN!$A$18:$E$71,5,0) -> 0.01 | G25: ='HR (OPIK)'!M25 -> 1 | H25: ='USER1-TAUFIK'!M25 -> 1 | I25: ='USER2-TAUFIK'!M25 -> 1 | J25: ='MANAGER-TAUFIK'!M25 -> 1 | K25: =AVERAGE(G25:J25) -> 1
B27: C | C27: HARD SKILL | E27: =E28 -> 0.35 | G27: =G28 -> 33 | H27: =H28 -> 28 | I27: =I28 -> 33 | J27: =J28 -> 29 | K27: =K28 -> 30.75
A28: C100 | B28: 1 | C28: =VLOOKUP($A28,PERTANYAAN!$A$18:$E$71,3,0) -> Operasi / Logistik | E28: =VLOOKUP($A28,PERTANYAAN!$A$18:$E$71,5,0) -> 0.35 | G28: =SUM(G29:G33) -> 33 | H28: =SUM(H29:H33) -> 28 | I28: =SUM(I29:I33) -> 33 | J28: =SUM(J29:J33) -> 29 | K28: =SUM(K29:K33) -> 30.75
A29: C110 | B29: - | C29: =VLOOKUP($A29,PERTANYAAN!$A$18:$E$71,3,0) -> Skill Mengemudi | D29: =VLOOKUP($A29,PERTANYAAN!$A$18:$E$71,4,0) -> Coba ceritakan pengalaman / keahlian dalam mengemudi mobil angkut/logistik? | E29: =VLOOKUP($A29,PERTANYAAN!$A$18:$E$71,5,0) -> 0.15 | G29: ='HR (OPIK)'!M29 -> 15 | H29: ='USER1-TAUFIK'!M29 -> 12 | I29: ='USER2-TAUFIK'!M29 -> 15 | J29: ='MANAGER-TAUFIK'!M29 -> 15 | K29: =AVERAGE(G29:J29) -> 14.25
A30: C120 | B30: - | C30: =VLOOKUP($A30,PERTANYAAN!$A$18:$E$71,3,0) -> Flow Administrasi Logistik | D30: =VLOOKUP($A30,PERTANYAAN!$A$18:$E$71,4,0) -> Coba ceritakan yang anda ketahui tentang alur administrasi logistik? Dan kaitannya dengan Ms. Office | E30: =VLOOKUP($A30,PERTANYAAN!$A$18:$E$71,5,0) -> 0.1 | G30: ='HR (OPIK)'!M30 -> 8 | H30: ='USER1-TAUFIK'!M30 -> 6 | I30: ='USER2-TAUFIK'!M30 -> 8 | J30: ='MANAGER-TAUFIK'!M30 -> 6 | K30: =AVERAGE(G30:J30) -> 7
A31: C130 | B31: - | C31: =VLOOKUP($A31,PERTANYAAN!$A$18:$E$71,3,0) -> Pengetahuan terkait logistik | D31: =VLOOKUP($A31,PERTANYAAN!$A$18:$E$71,4,0) -> Ceritakan yang anda ketahui terkait dengan logistik? | E31: =VLOOKUP($A31,PERTANYAAN!$A$18:$E$71,5,0) -> 0.025 | G31: ='HR (OPIK)'!M31 -> 2.5 | H31: ='USER1-TAUFIK'!M31 -> 2.5 | I31: ='USER2-TAUFIK'!M31 -> 2.5 | J31: ='MANAGER-TAUFIK'!M31 -> 2 | K31: =AVERAGE(G31:J31) -> 2.375
A32: C140 | B32: - | C32: =VLOOKUP($A32,PERTANYAAN!$A$18:$E$71,3,0) -> Pengalaman di Bongkar Muat | D32: =VLOOKUP($A32,PERTANYAAN!$A$18:$E$71,4,0) -> Apakah memiliki pengalaman terkait bongkar muat?sedalam apa? | E32: =VLOOKUP($A32,PERTANYAAN!$A$18:$E$71,5,0) -> 0.075 | G32: ='HR (OPIK)'!M32 -> 7.5 | H32: ='USER1-TAUFIK'!M32 -> 7.5 | I32: ='USER2-TAUFIK'!M32 -> 7.5 | J32: ='MANAGER-TAUFIK'!M32 -> 6 | K32: =AVERAGE(G32:J32) -> 7.125
B34: =B28+1 -> 2 | C34: Keuangan | E34: =SUM(E35:E37) -> 0.35
B35: - | C35: Skill Akuntansi & Input Data | E35: 0.15
B36: - | C36: Microsoft Office | E36: 0.2
B38: 3 | C38: Busdev & HR
B39: - | C39: Pengalaman Kreatif
B40: - | C40: Organisasi Perusahaan & Lembaga
B41: -
B43: D | C43: SOFT SKILL | E43: =E44 -> 0.25 | G43: =G44 -> 24.5 | H43: =H44 -> 16.5 | I43: =I44 -> 21 | J43: =J44 -> 16 | K43: =K44 -> 19.5
A44: D100 | B44: 1 | C44: =VLOOKUP($A44,PERTANYAAN!$A$18:$E$71,3,0) -> Staff | E44: =SUM(E45:E49) -> 0.25 | G44: =SUM(G45:G48) -> 24.5 | H44: =SUM(H45:H48) -> 16.5 | I44: =SUM(I45:I48) -> 21 | J44: =SUM(J45:J48) -> 16 | K44: =SUM(K45:K48) -> 19.5
A45: D110 | B45: - | C45: =VLOOKUP($A45,PERTANYAAN!$A$18:$E$71,3,0) -> Kepemimpinan | D45: =VLOOKUP($A45,PERTANYAAN!$A$18:$E$71,4,0) -> Jika terjadi suatu diskusi dalam group/kelompok yang belum menemukan titik temu, apa yang akan anda lakukan? | E45: =VLOOKUP($A45,PERTANYAAN!$A$18:$E$71,5,0) -> 0.025 | G45: ='HR (OPIK)'!M45 -> 2 | H45: ='USER1-TAUFIK'!M45 -> 0.5 | I45: ='USER2-TAUFIK'!M45 -> 1.5 | J45: ='MANAGER-TAUFIK'!M45 -> 1 | K45: =AVERAGE(G45:J45) -> 1.25
A46: D120 | B46: - | C46: =VLOOKUP($A46,PERTANYAAN!$A$18:$E$71,3,0) -> Komunikasi | D46: =VLOOKUP($A46,PERTANYAAN!$A$18:$E$71,4,0) -> Bagaimana hubungan kerjasama antar sesama pegawai / organisasi / kelompok?(jika memiliki pengalaman kerja) | E46: =VLOOKUP($A46,PERTANYAAN!$A$18:$E$71,5,0) -> 0.1 | G46: ='HR (OPIK)'!M46 -> 10 | H46: ='USER1-TAUFIK'!M46 -> 6 | I46: ='USER2-TAUFIK'!M46 -> 8 | J46: ='MANAGER-TAUFIK'!M46 -> 6 | K46: =AVERAGE(G46:J46) -> 7.5
A47: D130 | B47: - | C47: =VLOOKUP($A47,PERTANYAAN!$A$18:$E$71,3,0) -> Patuh pada Peraturan / Commitment | D47: =VLOOKUP($A47,PERTANYAAN!$A$18:$E$71,4,0) -> Bagaimana pandangan anda terkait perusahaan dan aturan yang dapat berubah ubah sesuai arah perusahaan? | E47: =VLOOKUP($A47,PERTANYAAN!$A$18:$E$71,5,0) -> 0.05 | G47: ='HR (OPIK)'!M47 -> 5 | H47: ='USER1-TAUFIK'!M47 -> 4 | I47: ='USER2-TAUFIK'!M47 -> 4 | J47: ='MANAGER-TAUFIK'!M47 -> 3 | K47: =AVERAGE(G47:J47) -> 4
A48: D140 | B48: - | C48: =VLOOKUP($A48,PERTANYAAN!$A$18:$E$71,3,0) -> Determinasi thd tekanan | D48: =VLOOKUP($A48,PERTANYAAN!$A$18:$E$71,4,0) -> Bagaimana pandangan anda jika anda dituntut pada pekerjaan diluar dari waktu normal dalam bekerja? | E48: =VLOOKUP($A48,PERTANYAAN!$A$18:$E$71,5,0) -> 0.075 | G48: ='HR (OPIK)'!M48 -> 7.5 | H48: ='USER1-TAUFIK'!M48 -> 6 | I48: ='USER2-TAUFIK'!M48 -> 7.5 | J48: ='MANAGER-TAUFIK'!M48 -> 6 | K48: =AVERAGE(G48:J48) -> 6.75
B50: 2 | C50: Supervisor
...

Sheet HASIL-DIAN
A1: FORM PENILAIAN PEGAWAI & CALON PEGAWAI
A2: DANISWARA GROUP
A5: NAMA | B5: : | C5: DIAN YUSUF
A6: POSISI PELAMAR | B6: : | C6: STAFF OPERASI
A7: PENEMPATAN | B7: : | C7: DKI - JABODETABEK
A8: DIVISI | B8: : | C8: OPERASI
A9: BUDGET SALARY | B9: : | C9: RANGE 4 JT - 4,8 JT (ALL IN - IKN)
A10: HR | B10: : | C10: ANGGY PERMANA PUTRA
A11: HASIL PENILAIAN | B11: : | C11: =K16 -> 86.233333
A13: KODE ACC | B13: NO. | C13: KATEGORI | D13: PERTANYAAN | E13: BOBOT | G13: PENILAIAN | K13: HASIL | L13: KETERANGAN
G14: HR | H14: USER-1 | I14: USER-2 | J14: MANAGER
C16: GRAND TOTAL PENILAIAN | E16: =E17+E21+E27+E43+E60+E65+E69 -> 1 | G16: =G17+G21+G27+G43+G60+G65+G69 -> 90.5 | H16: =H17+H21+H27+H43+H60+H65+H69 -> 88 | J16: =J17+J21+J27+J43+J60+J65+J69 -> 75.7 | K16: =K17+K21+K27+K43+K60+K65+K69 -> 86.233333
B17: A | C17: PENGALAMAN | E17: =SUM(E18:E19) -> 0.1 | G17: =SUM(G18:G20) -> 6 | H17: =SUM(H18:H20) -> 6 | J17: =SUM(J18:J20) -> 6 | K17: =SUM(K18:K20) -> 6
A18: A100 | B18: 1 | C18: =VLOOKUP($A18,PERTANYAAN!$A$18:$E$71,3,0) -> Pengalaman di dalam Daniswara Group | D18: =VLOOKUP($A18,PERTANYAAN!$A$18:$E$71,4,0) -> Apakah ada Pengalaman di Daniswara Group? Bagaimana pandangan anda terkait Daniswara Group? | E18: =VLOOKUP($A18,PERTANYAAN!$A$18:$E$71,5,0) -> 0.06 | G18: ='HR (DIAN)'!M18 -> 6 | H18: ='USER1-DIAN'!M18 -> 6 | J18: ='MANAGER-DIAN'!M18 -> 6 | K18: =AVERAGE(G18:J18) -> 6
A19: A200 | B19: =B18+1 -> 2 | C19: =VLOOKUP($A19,PERTANYAAN!$A$18:$E$71,3,0) -> Pengalaman di luar Daniswara Group | D19: =VLOOKUP($A19,PERTANYAAN!$A$18:$E$71,4,0) -> Jika tidak, apakah sudah ada pengalaman sejenis di luar Daniswara? | E19: =VLOOKUP($A19,PERTANYAAN!$A$18:$E$71,5,0) -> 0.04 | G19: ='HR (DIAN)'!M19 -> 0 | H19: ='USER1-DIAN'!M19 -> 0 | J19: ='MANAGER-DIAN'!M19 -> 0 | K19: =AVERAGE(G19:J19) -> 0
B21: B | C21: ADMINISTRASI | E21: =SUM(E22:E25) -> 0.05 | G21: =SUM(G22:G25) -> 4 | H21: =SUM(H22:H25) -> 4 | J21: =SUM(J22:J25) -> 1 | K21: =SUM(K22:K25) -> 3
A22: B100 | B22: 1 | C22: =VLOOKUP($A22,PERTANYAAN!$A$18:$E$71,3,0) -> Identitas (KTP & KK) | D22: =VLOOKUP($A22,PERTANYAAN!$A$18:$E$71,4,0) -> Apakah ada Identitas Diri KTP & KK? | E22: =VLOOKUP($A22,PERTANYAAN!$A$18:$E$71,5,0) -> 0.01 | G22: ='HR (DIAN)'!M22 -> 1 | H22: ='USER1-DIAN'!M22 -> 1 | J22: ='MANAGER-DIAN'!M22 -> 1 | K22: =AVERAGE(G22:J22) -> 1
A23: B200 | B23: =B22+1 -> 2 | C23: =VLOOKUP($A23,PERTANYAAN!$A$18:$E$71,3,0) -> SIM A (utk jabatan di Divisi Operasi) | D23: =VLOOKUP($A23,PERTANYAAN!$A$18:$E$71,4,0) -> Apakah sudah memiliki SIM A? | E23: =VLOOKUP($A23,PERTANYAAN!$A$18:$E$71,5,0) -> 0.02 | G23: ='HR (DIAN)'!M23 -> 2 | H23: ='USER1-DIAN'!M23 -> 2 | J23: ='MANAGER-DIAN'!M23 -> 0 | K23: =AVERAGE(G23:J23) -> 1.3333333
A24: B300 | B24: =B23+1 -> 3 | C24: =VLOOKUP($A24,PERTANYAAN!$A$18:$E$71,3,0) -> SIM C | D24: =VLOOKUP($A24,PERTANYAAN!$A$18:$E$71,4,0) -> Apakah sudah memiliki SIM C? | E24: =VLOOKUP($A24,PERTANYAAN!$A$18:$E$71,5,0) -> 0.01 | G24: ='HR (DIAN)'!M24 -> 1 | H24: ='USER1-DIAN'!M24 -> 1 | J24: ='MANAGER-DIAN'!M24 -> 0 | K24: =AVERAGE(G24:J24) -> 0.66666667
A25: B400 | B25: =B24+1 -> 4 | C25: =VLOOKUP($A25,PERTANYAAN!$A$18:$E$71,3,0) -> NPWP | D25: =VLOOKUP($A25,PERTANYAAN!$A$18:$E$71,4,0) -> Apakah sudah Memiliki NPWP? | E25: =VLOOKUP($A25,PERTANYAAN!$A$18:$E$71,5,0) -> 0.01 | G25: ='HR (DIAN)'!M25 -> 0 | H25: ='USER1-DIAN'!M25 -> 0 | J25: ='MANAGER-DIAN'!M25 -> 0 | K25: =AVERAGE(G25:J25) -> 0
B27: C | C27: HARD SKILL | E27: =E28 -> 0.35 | G27: =G28 -> 33 | H27: =H28 -> 35 | J27: =J28 -> 33 | K27: =K28 -> 33.666667
A28: C100 | B28: 1 | C28: =VLOOKUP($A28,PERTANYAAN!$A$18:$E$71,3,0) -> Operasi / Logistik | E28: =VLOOKUP($A28,PERTANYAAN!$A$18:$E$71,5,0) -> 0.35 | G28: =SUM(G29:G33) -> 33 | H28: =SUM(H29:H33) -> 35 | J28: =SUM(J29:J33) -> 33 | K28: =SUM(K29:K33) -> 33.666667
A29: C110 | B29: - | C29: =VLOOKUP($A29,PERTANYAAN!$A$18:$E$71,3,0) -> Skill Mengemudi | D29: =VLOOKUP($A29,PERTANYAAN!$A$18:$E$71,4,0) -> Coba ceritakan pengalaman / keahlian dalam mengemudi mobil angkut/logistik? | E29: =VLOOKUP($A29,PERTANYAAN!$A$18:$E$71,5,0) -> 0.15 | G29: ='HR (DIAN)'!M29 -> 15 | H29: ='USER1-DIAN'!M29 -> 15 | J29: ='MANAGER-DIAN'!M29 -> 15 | K29: =AVERAGE(G29:J29) -> 15
A30: C120 | B30: - | C30: =VLOOKUP($A30,PERTANYAAN!$A$18:$E$71,3,0) -> Flow Administrasi Logistik | D30: =VLOOKUP($A30,PERTANYAAN!$A$18:$E$71,4,0) -> Coba ceritakan yang anda ketahui tentang alur administrasi logistik? Dan kaitannya dengan Ms. Office | E30: =VLOOKUP($A30,PERTANYAAN!$A$18:$E$71,5,0) -> 0.1 | G30: ='HR (DIAN)'!M30 -> 8 | H30: ='USER1-DIAN'!M30 -> 10 | J30: ='MANAGER-DIAN'!M30 -> 8 | K30: =AVERAGE(G30:J30) -> 8.6666667
A31: C130 | B31: - | C31: =VLOOKUP($A31,PERTANYAAN!$A$18:$E$71,3,0) -> Pengetahuan terkait logistik | D31: =VLOOKUP($A31,PERTANYAAN!$A$18:$E$71,4,0) -> Ceritakan yang anda ketahui terkait dengan logistik? | E31: =VLOOKUP($A31,PERTANYAAN!$A$18:$E$71,5,0) -> 0.025 | G31: ='HR (DIAN)'!M31 -> 2.5 | H31: ='USER1-DIAN'!M31 -> 2.5 | J31: ='MANAGER-DIAN'!M31 -> 2.5 | K31: =AVERAGE(G31:J31) -> 2.5
A32: C140 | B32: - | C32: =VLOOKUP($A32,PERTANYAAN!$A$18:$E$71,3,0) -> Pengalaman di Bongkar Muat | D32: =VLOOKUP($A32,PERTANYAAN!$A$18:$E$71,4,0) -> Apakah memiliki pengalaman terkait bongkar muat?sedalam apa? | E32: =VLOOKUP($A32,PERTANYAAN!$A$18:$E$71,5,0) -> 0.075 | G32: ='HR (DIAN)'!M32 -> 7.5 | H32: ='USER1-DIAN'!M32 -> 7.5 | J32: ='MANAGER-DIAN'!M32 -> 7.5 | K32: =AVERAGE(G32:J32) -> 7.5
B34: =B28+1 -> 2 | C34: Keuangan | E34: =SUM(E35:E37) -> 0.35
B35: - | C35: Skill Akuntansi & Input Data | E35: 0.15
B36: - | C36: Microsoft Office | E36: 0.2
B38: 3 | C38: Busdev & HR
B39: - | C39: Pengalaman Kreatif
B40: - | C40: Organisasi Perusahaan & Lembaga
B41: -
B43: D | C43: SOFT SKILL | E43: =E44 -> 0.25 | G43: =G44 -> 24 | H43: =H44 -> 24 | J43: =J44 -> 19 | K43: =K44 -> 22.333333
A44: D100 | B44: 1 | C44: =VLOOKUP($A44,PERTANYAAN!$A$18:$E$71,3,0) -> Staff | E44: =SUM(E45:E49) -> 0.25 | G44: =SUM(G45:G48) -> 24 | H44: =SUM(H45:H48) -> 24 | J44: =SUM(J45:J48) -> 19 | K44: =SUM(K45:K48) -> 22.333333
A45: D110 | B45: - | C45: =VLOOKUP($A45,PERTANYAAN!$A$18:$E$71,3,0) -> Kepemimpinan | D45: =VLOOKUP($A45,PERTANYAAN!$A$18:$E$71,4,0) -> Jika terjadi suatu diskusi dalam group/kelompok yang belum menemukan titik temu, apa yang akan anda lakukan? | E45: =VLOOKUP($A45,PERTANYAAN!$A$18:$E$71,5,0) -> 0.025 | G45: ='HR (DIAN)'!M45 -> 2.5 | H45: ='USER1-DIAN'!M45 -> 2.5 | J45: ='MANAGER-DIAN'!M45 -> 2 | K45: =AVERAGE(G45:J45) -> 2.3333333
A46: D120 | B46: - | C46: =VLOOKUP($A46,PERTANYAAN!$A$18:$E$71,3,0) -> Komunikasi | D46: =VLOOKUP($A46,PERTANYAAN!$A$18:$E$71,4,0) -> Bagaimana hubungan kerjasama antar sesama pegawai / organisasi / kelompok?(jika memiliki pengalaman kerja) | E46: =VLOOKUP($A46,PERTANYAAN!$A$18:$E$71,5,0) -> 0.1 | G46: ='HR (DIAN)'!M46 -> 10 | H46: ='USER1-DIAN'!M46 -> 10 | J46: ='MANAGER-DIAN'!M46 -> 8 | K46: =AVERAGE(G46:J46) -> 9.3333333
A47: D130 | B47: - | C47: =VLOOKUP($A47,PERTANYAAN!$A$18:$E$71,3,0) -> Patuh pada Peraturan / Commitment | D47: =VLOOKUP($A47,PERTANYAAN!$A$18:$E$71,4,0) -> Bagaimana pandangan anda terkait perusahaan dan aturan yang dapat berubah ubah sesuai arah perusahaan? | E47: =VLOOKUP($A47,PERTANYAAN!$A$18:$E$71,5,0) -> 0.05 | G47: ='HR (DIAN)'!M47 -> 4 | H47: ='USER1-DIAN'!M47 -> 4 | J47: ='MANAGER-DIAN'!M47 -> 3 | K47: =AVERAGE(G47:J47) -> 3.6666667
A48: D140 | B48: - | C48: =VLOOKUP($A48,PERTANYAAN!$A$18:$E$71,3,0) -> Determinasi thd tekanan | D48: =VLOOKUP($A48,PERTANYAAN!$A$18:$E$71,4,0) -> Bagaimana pandangan anda jika anda dituntut pada pekerjaan diluar dari waktu normal dalam bekerja? | E48: =VLOOKUP($A48,PERTANYAAN!$A$18:$E$71,5,0) -> 0.075 | G48: ='HR (DIAN)'!M48 -> 7.5 | H48: ='USER1-DIAN'!M48 -> 7.5 | J48: ='MANAGER-DIAN'!M48 -> 6 | K48: =AVERAGE(G48:J48) -> 7
B50: 2 | C50: Supervisor
...

Sheet HR (SADAM)
A1: FORM PENILAIAN PEGAWAI & CALON PEGAWAI
A2: DANISWARA GROUP
A5: NAMA | B5: : | C5: SADAM | L5: KETERANGAN
A6: POSISI PELAMAR | B6: : | C6: STAFF OPERASI | L6: SK | M6: : | N6: SANGAT KURANG
A7: PENEMPATAN | B7: : | C7: IKN - KALIMANTAN TIMUR | L7: K | M7: : | N7: KURANG
A8: DIVISI | B8: : | C8: OPERASI | L8: R | M8: : | N8: RATA-RATA
A9: BUDGET SALARY | B9: : | C9: RANGE 4 JT - 4,8 JT (ALL IN - IKN) | L9: B | M9: : | N9: BAIK
A10: PENILAI | B10: : | C10: ANGGY PERMANA PUTRA | D10: (HR) | L10: SB | M10: : | N10: SANGAT BAIK
A11: HASIL PENILAIAN | B11: : | C11: =M16 -> 48.7
A13: KODE ACC | B13: NO. | C13: KATEGORI | D13: BOBOT | F13: CHECK | H13: PENILAIAN | M13: HASIL | N13: KETERANGAN
F14: ADA | G14: TIDAK | H14: SK | I14: K | J14: R | K14: B | L14: SB
H15: 0.2 | I15: 0.4 | J15: 0.6 | K15: 0.8 | L15: 1
C16: GRAND TOTAL PENILAIAN | M16: =M17+M21+M27+M43+M60+M65+M69 -> 48.7
B17: A | C17: PENGALAMAN (jika ada) | D17: =SUM(D18:D19) -> 0.1 | M17: =SUM(M18:M20) -> 0
A18: A100 | B18: 1 | C18: =VLOOKUP($A18,PERTANYAAN!$A$18:$E$71,3,0) -> Pengalaman di dalam Daniswara Group | D18: =VLOOKUP($A18,PERTANYAAN!$A$18:$E$71,5,0) -> 0.06 | M18: =IF(F18="V",D18*100,0) -> 0
A19: A200 | B19: =B18+1 -> 2 | C19: =VLOOKUP($A19,PERTANYAAN!$A$18:$E$71,3,0) -> Pengalaman di luar Daniswara Group | D19: =VLOOKUP($A19,PERTANYAAN!$A$18:$E$71,5,0) -> 0.04 | M19: =IF(F19="V",D19*100,0) -> 0
B21: B | C21: ADMINISTRASI | D21: =SUM(D22:D25) -> 0.05 | M21: =SUM(M22:M25) -> 5
A22: B100 | B22: 1 | C22: =VLOOKUP($A22,PERTANYAAN!$A$18:$E$71,3,0) -> Identitas (KTP & KK) | D22: =VLOOKUP($A22,PERTANYAAN!$A$18:$E$71,5,0) -> 0.01 | F22: V | M22: =IF(F22="V",D22*100,0) -> 1
A23: B200 | B23: =B22+1 -> 2 | C23: =VLOOKUP($A23,PERTANYAAN!$A$18:$E$71,3,0) -> SIM A (utk jabatan di Divisi Operasi) | D23: =VLOOKUP($A23,PERTANYAAN!$A$18:$E$71,5,0) -> 0.02 | F23: V | M23: =IF(F23="V",D23*100,0) -> 2
A24: B300 | B24: =B23+1 -> 3 | C24: =VLOOKUP($A24,PERTANYAAN!$A$18:$E$71,3,0) -> SIM C | D24: =VLOOKUP($A24,PERTANYAAN!$A$18:$E$71,5,0) -> 0.01 | F24: V | M24: =IF(F24="V",D24*100,0) -> 1
A25: B400 | B25: =B24+1 -> 4 | C25: =VLOOKUP($A25,PERTANYAAN!$A$18:$E$71,3,0) -> NPWP | D25: =VLOOKUP($A25,PERTANYAAN!$A$18:$E$71,5,0) -> 0.01 | F25: V | M25: =IF(F25="V",D25*100,0) -> 1
B27: C | C27: HARD SKILL | D27: =D28 -> 0.35 | M27: =M28 -> 14
A28: C100 | B28: 1 | C28: =VLOOKUP($A28,PERTANYAAN!$A$18:$E$71,3,0) -> Operasi / Logistik | D28: =VLOOKUP($A28,PERTANYAAN!$A$18:$E$71,5,0) -> 0.35 | M28: =SUM(M29:M33) -> 14
A29: C110 | B29: - | C29: =VLOOKUP($A29,PERTANYAAN!$A$18:$E$71,3,0) -> Skill Mengemudi | D29: =VLOOKUP($A29,PERTANYAAN!$A$18:$E$71,5,0) -> 0.15 | I29: V | M29: =IF(H29="V",$D29*H$15,IF(I29="V",$D29*I$15,IF(J29="V",$D29*J$15,IF(K29="V",$D29*K$15,IF(L29="V",$D29*L$15,0)))))*100 -> 6
A30: C120 | B30: - | C30: =VLOOKUP($A30,PERTANYAAN!$A$18:$E$71,3,0) -> Flow Administrasi Logistik | D30: =VLOOKUP($A30,PERTANYAAN!$A$18:$E$71,5,0) -> 0.1 | I30: V | M30: =IF(H30="V",$D30*H$15,IF(I30="V",$D30*I$15,IF(J30="V",$D30*J$15,IF(K30="V",$D30*K$15,IF(L30="V",$D30*L$15,0)))))*100 -> 4
A31: C130 | B31: - | C31: =VLOOKUP($A31,PERTANYAAN!$A$18:$E$71,3,0) -> Pengetahuan terkait logistik | D31: =VLOOKUP($A31,PERTANYAAN!$A$18:$E$71,5,0) -> 0.025 | I31: V | M31: =IF(H31="V",$D31*H$15,IF(I31="V",$D31*I$15,IF(J31="V",$D31*J$15,IF(K31="V",$D31*K$15,IF(L31="V",$D31*L$15,0)))))*100 -> 1
A32: C140 | B32: - | C32: =VLOOKUP($A32,PERTANYAAN!$A$18:$E$71,3,0) -> Pengalaman di Bongkar Muat | D32: =VLOOKUP($A32,PERTANYAAN!$A$18:$E$71,5,0) -> 0.075 | I32: V | M32: =IF(H32="V",$D32*H$15,IF(I32="V",$D32*I$15,IF(J32="V",$D32*J$15,IF(K32="V",$D32*K$15,IF(L32="V",$D32*L$15,0)))))*100 -> 3
B34: =B28+1 -> 2 | C34: Keuangan | D34: =SUM(D35:D37) -> 0.35
B35: - | C35: Skill Akuntansi & Input Data | D35: 0.15
B36: - | C36: Microsoft Office | D36: 0.2
B38: 3 | C38: Busdev & HR
B39: - | C39: Pengalaman Kreatif
B40: - | C40: Organisasi Perusahaan & Lembaga
B41: -
B43: D | C43: SOFT SKILL | D43: =D44 -> 0.25 | M43: =M44 -> 14
A44: D100 | B44: 1 | C44: =VLOOKUP($A44,PERTANYAAN!$A$18:$E$71,3,0) -> Staff | D44: =VLOOKUP($A44,PERTANYAAN!$A$18:$E$71,5,0) -> 0.25 | M44: =SUM(M45:M48) -> 14
A45: D110 | B45: - | C45: =VLOOKUP($A45,PERTANYAAN!$A$18:$E$71,3,0) -> Kepemimpinan | D45: =VLOOKUP($A45,PERTANYAAN!$A$18:$E$71,5,0) -> 0.025 | I45: V | M45: =IF(H45="V",$D45*H$15,IF(I45="V",$D45*I$15,IF(J45="V",$D45*J$15,IF(K45="V",$D45*K$15,IF(L45="V",$D45*L$15,0)))))*100 -> 1
A46: D120 | B46: - | C46: =VLOOKUP($A46,PERTANYAAN!$A$18:$E$71,3,0) -> Komunikasi | D46: =VLOOKUP($A46,PERTANYAAN!$A$18:$E$71,5,0) -> 0.1 | J46: V | M46: =IF(H46="V",$D46*H$15,IF(I46="V",$D46*I$15,IF(J46="V",$D46*J$15,IF(K46="V",$D46*K$15,IF(L46="V",$D46*L$15,0)))))*100 -> 6
A47: D130 | B47: - | C47: =VLOOKUP($A47,PERTANYAAN!$A$18:$E$71,3,0) -> Patuh pada Peraturan / Commitment | D47: =VLOOKUP($A47,PERTANYAAN!$A$18:$E$71,5,0) -> 0.05 | K47: V | M47: =IF(H47="V",$D47*H$15,IF(I47="V",$D47*I$15,IF(J47="V",$D47*J$15,IF(K47="V",$D47*K$15,IF(L47="V",$D47*L$15,0)))))*100 -> 4
A48: D140 | B48: - | C48: =VLOOKUP($A48,PERTANYAAN!$A$18:$E$71,3,0) -> Determinasi thd tekanan | D48: =VLOOKUP($A48,PERTANYAAN!$A$18:$E$71,5,0) -> 0.075 | I48: V | M48: =IF(H48="V",$D48*H$15,IF(I48="V",$D48*I$15,IF(J48="V",$D48*J$15,IF(K48="V",$D48*K$15,IF(L48="V",$D48*L$15,0)))))*100 -> 3
...

Sheet HR (IMAN)
A1: FORM PENILAIAN PEGAWAI & CALON PEGAWAI
A2: DANISWARA GROUP
A5: NAMA | B5: : | C5: IMAN | L5: KETERANGAN
A6: POSISI PELAMAR | B6: : | C6: STAFF OPERASI | L6: SK | M6: : | N6: SANGAT KURANG
A7: PENEMPATAN | B7: : | C7: IKN - KALIMANTAN TIMUR | L7: K | M7: : | N7: KURANG
A8: DIVISI | B8: : | C8: OPERASI | L8: R | M8: : | N8: RATA-RATA
A9: BUDGET SALARY | B9: : | C9: RANGE 4 JT - 4,8 JT (ALL IN - IKN) | L9: B | M9: : | N9: BAIK
A10: PENILAI | B10: : | C10: ANGGY PERMANA PUTRA | D10: (HR) | L10: SB | M10: : | N10: SANGAT BAIK
A11: HASIL PENILAIAN | B11: : | C11: =M16 -> 79.7
A13: KODE ACC | B13: NO. | C13: KATEGORI | D13: BOBOT | F13: CHECK | H13: PENILAIAN | M13: HASIL | N13: KETERANGAN
F14: ADA | G14: TIDAK | H14: SK | I14: K | J14: R | K14: B | L14: SB
H15: 0.2 | I15: 0.4 | J15: 0.6 | K15: 0.8 | L15: 1
C16: GRAND TOTAL PENILAIAN | M16: =M17+M21+M27+M43+M60+M65+M69 -> 79.7
B17: A | C17: PENGALAMAN (jika ada) | D17: =SUM(D18:D19) -> 0.1 | M17: =SUM(M18:M20) -> 4
A18: A100 | B18: 1 | C18: =VLOOKUP($A18,PERTANYAAN!$A$18:$E$71,3,0) -> Pengalaman di dalam Daniswara Group | D18: =VLOOKUP($A18,PERTANYAAN!$A$18:$E$71,5,0) -> 0.06 | M18: =IF(F18="V",D18*100,0) -> 0
A19: A200 | B19: =B18+1 -> 2 | C19: =VLOOKUP($A19,PERTANYAAN!$A$18:$E$71,3,0) -> Pengalaman di luar Daniswara Group | D19: =VLOOKUP($A19,PERTANYAAN!$A$18:$E$71,5,0) -> 0.04 | F19: V | M19: =IF(F19="V",D19*100,0) -> 4
B21: B | C21: ADMINISTRASI | D21: =SUM(D22:D25) -> 0.05 | M21: =SUM(M22:M25) -> 4
A22: B100 | B22: 1 | C22: =VLOOKUP($A22,PERTANYAAN!$A$18:$E$71,3,0) -> Identitas (KTP & KK) | D22: =VLOOKUP($A22,PERTANYAAN!$A$18:$E$71,5,0) -> 0.01 | F22: V | M22: =IF(F22="V",D22*100,0) -> 1
A23: B200 | B23: =B22+1 -> 2 | C23: =VLOOKUP($A23,PERTANYAAN!$A$18:$E$71,3,0) -> SIM A (utk jabatan di Divisi Operasi) | D23: =VLOOKUP($A23,PERTANYAAN!$A$18:$E$71,5,0) -> 0.02 | F23: V | M23: =IF(F23="V",D23*100,0) -> 2
A24: B300 | B24: =B23+1 -> 3 | C24: =VLOOKUP($A24,PERTANYAAN!$A$18:$E$71,3,0) -> SIM C | D24: =VLOOKUP($A24,PERTANYAAN!$A$18:$E$71,5,0) -> 0.01 | M24: =IF(F24="V",D24*100,0) -> 0
A25: B400 | B25: =B24+1 -> 4 | C25: =VLOOKUP($A25,PERTANYAAN!$A$18:$E$71,3,0) -> NPWP | D25: =VLOOKUP($A25,PERTANYAAN!$A$18:$E$71,5,0) -> 0.01 | F25: V | M25: =IF(F25="V",D25*100,0) -> 1
B27: C | C27: HARD SKILL | D27: =D28 -> 0.35 | M27: =M28 -> 30.5
A28: C100 | B28: 1 | C28: =VLOOKUP($A28,PERTANYAAN!$A$18:$E$71,3,0) -> Operasi / Logistik | D28: =VLOOKUP($A28,PERTANYAAN!$A$18:$E$71,5,0) -> 0.35 | M28: =SUM(M29:M33) -> 30.5
A29: C110 | B29: - | C29: =VLOOKUP($A29,PERTANYAAN!$A$18:$E$71,3,0) -> Skill Mengemudi | D29: =VLOOKUP($A29,PERTANYAAN!$A$18:$E$71,5,0) -> 0.15 | L29: V | M29: =IF(H29="V",$D29*H$15,IF(I29="V",$D29*I$15,IF(J29="V",$D29*J$15,IF(K29="V",$D29*K$15,IF(L29="V",$D29*L$15,0)))))*100 -> 15
A30: C120 | B30: - | C30: =VLOOKUP($A30,PERTANYAAN!$A$18:$E$71,3,0) -> Flow Administrasi Logistik | D30: =VLOOKUP($A30,PERTANYAAN!$A$18:$E$71,5,0) -> 0.1 | J30: V | M30: =IF(H30="V",$D30*H$15,IF(I30="V",$D30*I$15,IF(J30="V",$D30*J$15,IF(K30="V",$D30*K$15,IF(L30="V",$D30*L$15,0)))))*100 -> 6
A31: C130 | B31: - | C31: =VLOOKUP($A31,PERTANYAAN!$A$18:$E$71,3,0) -> Pengetahuan terkait logistik | D31: =VLOOKUP($A31,PERTANYAAN!$A$18:$E$71,5,0) -> 0.025 | K31: V | M31: =IF(H31="V",$D31*H$15,IF(I31="V",$D31*I$15,IF(J31="V",$D31*J$15,IF(K31="V",$D31*K$15,IF(L31="V",$D31*L$15,0)))))*100 -> 2
A32: C140 | B32: - | C32: =VLOOKUP($A32,PERTANYAAN!$A$18:$E$71,3,0) -> Pengalaman di Bongkar Muat | D32: =VLOOKUP($A32,PERTANYAAN!$A$18:$E$71,5,0) -> 0.075 | L32: V | M32: =IF(H32="V",$D32*H$15,IF(I32="V",$D32*I$15,IF(J32="V",$D32*J$15,IF(K32="V",$D32*K$15,IF(L32="V",$D32*L$15,0)))))*100 -> 7.5
B34: =B28+1 -> 2 | C34: Keuangan | D34: =SUM(D35:D37) -> 0.35
B35: - | C35: Skill Akuntansi & Input Data | D35: 0.15
B36: - | C36: Microsoft Office | D36: 0.2
B38: 3 | C38: Busdev & HR
B39: - | C39: Pengalaman Kreatif
B40: - | C40: Organisasi Perusahaan & Lembaga
B41: -
B43: D | C43: SOFT SKILL | D43: =D44 -> 0.25 | M43: =M44 -> 20.5
A44: D100 | B44: 1 | C44: =VLOOKUP($A44,PERTANYAAN!$A$18:$E$71,3,0) -> Staff | D44: =VLOOKUP($A44,PERTANYAAN!$A$18:$E$71,5,0) -> 0.25 | M44: =SUM(M45:M48) -> 20.5
A45: D110 | B45: - | C45: =VLOOKUP($A45,PERTANYAAN!$A$18:$E$71,3,0) -> Kepemimpinan | D45: =VLOOKUP($A45,PERTANYAAN!$A$18:$E$71,5,0) -> 0.025 | I45: V | M45: =IF(H45="V",$D45*H$15,IF(I45="V",$D45*I$15,IF(J45="V",$D45*J$15,IF(K45="V",$D45*K$15,IF(L45="V",$D45*L$15,0)))))*100 -> 1
A46: D120 | B46: - | C46: =VLOOKUP($A46,PERTANYAAN!$A$18:$E$71,3,0) -> Komunikasi | D46: =VLOOKUP($A46,PERTANYAAN!$A$18:$E$71,5,0) -> 0.1 | K46: V | M46: =IF(H46="V",$D46*H$15,IF(I46="V",$D46*I$15,IF(J46="V",$D46*J$15,IF(K46="V",$D46*K$15,IF(L46="V",$D46*L$15,0)))))*100 -> 8
A47: D130 | B47: - | C47: =VLOOKUP($A47,PERTANYAAN!$A$18:$E$71,3,0) -> Patuh pada Peraturan / Commitment | D47: =VLOOKUP($A47,PERTANYAAN!$A$18:$E$71,5,0) -> 0.05 | K47: V | M47: =IF(H47="V",$D47*H$15,IF(I47="V",$D47*I$15,IF(J47="V",$D47*J$15,IF(K47="V",$D47*K$15,IF(L47="V",$D47*L$15,0)))))*100 -> 4
A48: D140 | B48: - | C48: =VLOOKUP($A48,PERTANYAAN!$A$18:$E$71,3,0) -> Determinasi thd tekanan | D48: =VLOOKUP($A48,PERTANYAAN!$A$18:$E$71,5,0) -> 0.075 | L48: V | M48: =IF(H48="V",$D48*H$15,IF(I48="V",$D48*I$15,IF(J48="V",$D48*J$15,IF(K48="V",$D48*K$15,IF(L48="V",$D48*L$15,0)))))*100 -> 7.5
...

Sheet HR (DENY)
A1: FORM PENILAIAN PEGAWAI & CALON PEGAWAI
A2: DANISWARA GROUP
A5: NAMA | B5: : | C5: DENY FERDIANSYAH | L5: KETERANGAN
A6: POSISI PELAMAR | B6: : | C6: STAFF OPERASI | L6: SK | M6: : | N6: SANGAT KURANG
A7: PENEMPATAN | B7: : | C7: IKN - KALIMANTAN TIMUR | L7: K | M7: : | N7: KURANG
A8: DIVISI | B8: : | C8: OPERASI | L8: R | M8: : | N8: RATA-RATA
A9: BUDGET SALARY | B9: : | C9: RANGE 4 JT - 4,8 JT (ALL IN - IKN) | L9: B | M9: : | N9: BAIK
A10: PENILAI | B10: : | C10: ANGGY PERMANA PUTRA | D10: (HR) | L10: SB | M10: : | N10: SANGAT BAIK
A11: HASIL PENILAIAN | B11: : | C11: =M16 -> 88
A13: KODE ACC | B13: NO. | C13: KATEGORI | D13: BOBOT | F13: CHECK | H13: PENILAIAN | M13: HASIL | N13: KETERANGAN
F14: ADA | G14: TIDAK | H14: SK | I14: K | J14: R | K14: B | L14: SB
H15: 0.2 | I15: 0.4 | J15: 0.6 | K15: 0.8 | L15: 1
C16: GRAND TOTAL PENILAIAN | M16: =M17+M21+M27+M43+M60+M65+M69 -> 88
